Workbook
Name 近战: 设定器!$H$36:$K$36
Name 远程: 设定器!$H$37:$K$37
Name 自动化: 设定器!$H$38:$K$38
Name space: 地图模拟!$AE$16
Name 防御圈: [1]结算!$AE$16
Name 太空: [1]结算!$AE$16

Sheet 首页
A1: {=IFERROR(_xlfn.IFS(设定器!I2="地球联合军",战斗规则!A27,设定器!I2="拜隆军",战斗规则!A29,设定器!I2="马克西翁军",战斗规则!A31),"")} -> =DISPIMG("ID_F61B406E8105401E828C43F4FA2F2B71",1) | B1: 机体番号 | C1: =IF(IFERROR(设定器!C2,"")=0,"",IFERROR(设定器!C2,"")) -> bEXM-21(W) WeirdNova | E1: =IF(设定器!K9="All Clear","允许出击","整备中") -> 允许出击
B2: 行动代号 | C2: =IF(IFERROR(设定器!F2,"")=0,"",IFERROR(设定器!F2,"")) -> 加坦杰厄 | E2: =_xlfn.DISPIMG("ID_75E52D19E0964684BC5C4AAE91C51834",1) -> =DISPIMG("ID_75E52D19E0964684BC5C4AAE91C51834",1)
A3: 特性 | B3: {=IFERROR(_xlfn.IFS(OR(B4>14,(B4-B5)>8),"近战特化",OR(B5>14,(B5-B4)>8),"射击特化")," ")} -> 近战特化 | C3: {=IFERROR(_xlfn.IFS(AND(B6>130,B6*0.1-B7>8),"高血量",AND(B7>13,B7-B6*0.1>8),"高机动")," ")} | D3: =IF(IFERROR(设定器!B9,"")=0,"",IFERROR(设定器!B9,""))
A4: 格斗 | B4: =设定器!D9 -> 15
A5: 射击 | B5: =设定器!E9 -> 0
A6: 总血量 | B6: =设定器!F9*10 -> 150
A7: 机动 | B7: =设定器!G9 -> 10
A9: 技能名 | B9: 技能类型 | C9: 属性选择 | D9: 可选效果 | E9: =_xlfn.DISPIMG("ID_ED1C572086AD4798975CFCC7431E65B5",1) -> =DISPIMG("ID_ED1C572086AD4798975CFCC7431E65B5",1)
A10: {=IFERROR(_xlfn._xlws.FILTER(INDEX(设定器!$C$12:$F$22,,_xlfn.XMATCH(A$9,设定器!$C$11:$F$11)),INDEX(设定器!$C$12:$F$22,,_xlfn.XMATCH(A$9,设定器!$C$11:$F$11))<>""),"")} -> 撕裂 | B10: {=IFERROR(_xlfn._xlws.FILTER(INDEX(设定器!$C$12:$F$22,,_xlfn.XMATCH(B$9,设定器!$C$11:$F$11)),INDEX(设定器!$C$12:$F$22,,_xlfn.XMATCH(B$9,设定器!$C$11:$F$11))<>""),"")} -> 近战 | C10: {=IFERROR(_xlfn._xlws.FILTER(INDEX(设定器!$C$12:$F$22,,_xlfn.XMATCH(C$9,设定器!$C$11:$F$11)),INDEX(设定器!$C$12:$F$22,,_xlfn.XMATCH(C$9,设定器!$C$11:$F$11))<>""),"")} -> 实体 | D10: {=IFERROR(_xlfn._xlws.FILTER(INDEX(设定器!$C$12:$F$22,,_xlfn.XMATCH(D$9,设定器!$C$11:$F$11)),INDEX(设定器!$C$12:$F$22,,_xlfn.XMATCH(D$9,设定器!$C$11:$F$11))<>""),"")} -> 长柄
A11: 诱捕 | B11: 近战 | C11: 实体 | D11: 反击
A12: D-field | B12: 自动化 | C12: 光束 | D12: 守护
A13: mega收束炮击 | B13: 远程 | C13: 光束 | D13: 稳定
A14: mega扩散炮击 | B14: 远程 | C14: 光束 | D14: 扫射
A15: 有线式双发炮 | B15: 自动化 | C15: 光束 | D15: 助攻 | E15: =_xlfn.DISPIMG("ID_7CE6DCB9891D4141AFFB936FE1429621",1) -> =DISPIMG("ID_7CE6DCB9891D4141AFFB936FE1429621",1)
A16: 有线式双发炮 | B16: 自动化 | C16: 光束 | D16: 阻碍
A17: 移动补给单元 | B17: 近战 | D17: 补给（双槽）
A18: 移动补给单元 | B18: 近战 | D18: 补给（双槽）

Sheet 设定器
A1: 作品设定器beta1.0 | H1: 保存到本地再编辑！！！ | L1: 1.填写自己的各项单位类型，获得不同的属性点 2.将获得的点数按规则自由分配到 《格斗/射击/结构/机动》四个维度。 3.根据类型同时拥有不同数量的技能槽。 技能槽可供设计选择不同的技能类型，具体请下滑页面查看。
A2: 机体番号 | C2: bEXM-21(W) WeirdNova | E2: 行动代号 | F2: 加坦杰厄 | H2: 所属阵营 | I2: 拜隆军
A3: 单位 | B3: 类型 | C3: 总点数（p） | D3: 格斗 | E3: 射击 | F3: 结构 （>=1） | G3: 机动 | H3: 技能槽数量 | I3: 检查 | J3: 剩余点数 | K3: 数值要求
A4: 主机体 | B4: 机体 | C4: =IFERROR(VLOOKUP(B4,CHOOSE({1,2},$B$27:$B$32,$C$27:$C$32),2,FALSE),"") -> 40 | D4: 15 | E4: 0 | F4: 15 | G4: 10 | H4: =IFERROR(VLOOKUP(B4,CHOOSE({1,2},$B$27:$B$32,$N$27:$N$32),2,FALSE),"0") -> 3 | I4: {=IF(SUMPRODUCT(--(C4:G4<>""))=0,"",IF(AND(F4>=1,OR(B4=$B$27,D4+E4+F4+G4<=$C$27)),"STANDBY","PREPARING"))} -> STANDBY | J4: {=IFERROR(_xlfn.IFS((D4+E4+F4+G4)=0,C4,(D4+E4+F4+G4)>0,SUM(C4-(D4+E4+F4+G4))),"")} -> 0 | K4: =IF(I4="PREPARING",VLOOKUP(B4,CHOOSE({1,2},$B$27:$B$32,$H$27:$H$32),2,FALSE),"")
A5: 跟随 | B5: Royroy | C5: =IFERROR(VLOOKUP(B5,CHOOSE({1,2},$B$27:$B$32,$C$27:$C$32),2,FALSE),"") -> 25 | D5: 0 | E5: 20 | F5: 5 | G5: 0 | H5: =IFERROR(VLOOKUP(B5,CHOOSE({1,2},$B$27:$B$32,$N$27:$N$32),2,FALSE),"0") -> 2 | I5: {=IF(SUMPRODUCT(--(C5:G5<>""))=0,"",IF(AND(F5>=1,OR(D5>9,E5>9,F5>9,G5>9),D5+E5+F5+G5<=$C$27),"STANDBY","PREPARING"))} -> STANDBY | J5: {=IFERROR(_xlfn.IFS((D5+E5+F5+G5)=0,C5,(D5+E5+F5+G5)>0,SUM(C5-(D5+E5+F5+G5))),"")} -> 0 | K5: =IF(I5="PREPARING",VLOOKUP(B5,CHOOSE({1,2},$B$27:$B$32,$H$27:$H$32),2,FALSE),"")
A6: 右手 | B6: 武器 | C6: =IFERROR(VLOOKUP(B6,CHOOSE({1,2},$B$27:$B$32,$C$27:$C$32),2,FALSE),"") -> 15 | D6: 0 | E6: 14 | F6: 1 | G6: 0 | H6: =IFERROR(VLOOKUP(B6,CHOOSE({1,2},$B$27:$B$32,$N$27:$N$32),2,FALSE),"0") -> 1 | I6: {=IF(SUMPRODUCT(--(C6:G6<>""))=0,"",IF(AND(F6>=1,D6+E6+F6+G6<=$C$27),"STANDBY","PREPARING"))} -> STANDBY | J6: {=IFERROR(_xlfn.IFS((D6+E6+F6+G6)=0,C6,(D6+E6+F6+G6)>0,SUM(C6-(D6+E6+F6+G6))),"")} -> 0 | K6: =IF(I6="PREPARING",VLOOKUP(B6,CHOOSE({1,2},$B$27:$B$32,$H$27:$H$32),2,FALSE),"")
A7: 左手 | B7: 武器 | C7: =IFERROR(VLOOKUP(B7,CHOOSE({1,2},$B$27:$B$32,$C$27:$C$32),2,FALSE),"") -> 15 | D7: 0 | E7: 14 | F7: 1 | G7: 0 | H7: =IFERROR(VLOOKUP(B7,CHOOSE({1,2},$B$27:$B$32,$N$27:$N$32),2,FALSE),"0") -> 1 | I7: {=IF(SUMPRODUCT(--(C7:G7<>""))=0,"",IF(AND(F7>=1,OR(B7=$B$27,D7+E7+F7+G7<=$C$27)),"STANDBY","PREPARING"))} -> STANDBY | J7: {=IFERROR(_xlfn.IFS((D7+E7+F7+G7)=0,C7,(D7+E7+F7+G7)>0,SUM(C7-(D7+E7+F7+G7))),"")} -> 0 | K7: =IF(I7="PREPARING",VLOOKUP(B7,CHOOSE({1,2},$B$27:$B$32,$H$27:$H$32),2,FALSE),"")
A8: 其它 | B8: 载具 | C8: =IFERROR(VLOOKUP(B8,CHOOSE({1,2},$B$27:$B$32,$C$27:$C$32),2,FALSE),"") -> 15 | D8: 3 | E8: 0 | F8: 2 | G8: 10 | H8: =IFERROR(VLOOKUP(B8,CHOOSE({1,2},$B$27:$B$32,$N$27:$N$32),2,FALSE),"0") -> 2 | I8: {=IF(SUMPRODUCT(--(C8:G8<>""))=0,"",IF(AND(F8>=1,OR(B8=$B$27,D8+E8+F8+G8<=$C$27)),"STANDBY","PREPARING"))} -> STANDBY | J8: {=IFERROR(_xlfn.IFS((D8+E8+F8+G8)=0,C8,(D8+E8+F8+G8)>0,SUM(C8-(D8+E8+F8+G8))),"")} -> 0 | K8: =IF(I8="PREPARING",VLOOKUP(B8,CHOOSE({1,2},$B$27:$B$32,$H$27:$H$32),2,FALSE),"")
A9: 特殊加成 | C9: 合计 | D9: =SUMIF(B$4:B$8,$B$27,D$4:D$8)+SUMIF(B$4:B$8,B32,D$4:D$8) -> 15 | E9: =SUMIF($B$4:$B$8,$B$27,E$4:E$8) -> 0 | F9: =SUMIF($B$4:$B$8,$B$27,F$4:F$8) -> 15 | G9: =SUMIF($B$4:$B$8,$B$27,G$4:G$8) -> 10 | H9: =SUM(H4:H8) -> 9 | I9: 系统检查 | K9: {=_xlfn.IFS(AND(COUNTIF(I4:I8,"STANDBY")=0,COUNTIF(I4:I8,"PREPARING")=0)," ",AND(COUNTIF(I4:I8,"PREPARING")=0,COUNTIF(I4:I8,"STANDBY")>0),"All Clear",AND(COUNTIF(I4:I8,"PREPARING")>0,COUNTIF(I4:I8,"STANDBY")>0),"Loading")} -> All Clear
A10: 1.蓝色空为自己填写区域，绿色为编辑好的下拉菜单，单元格显示红条纹表示不可填。 2.填写完系统检查显示all clear即视为填写成功，到首页截图。 3.保存到本地再编辑！！！保存到本地再编辑！！！保存到本地再编辑！！！
A11: 单位 | B11: 技能槽编号 | C11: 技能名 | D11: 技能类型 | E11: 属性选择 | F11: 可选效果 | G11: 攻击距离 | H11: 特性效果
A12: 主机体 | B12: =IF(VALUE($H$4)<1,"无","1") -> 1 | C12: 撕裂 | D12: 近战 | E12: 实体 | F12: 长柄 | G12: {=IF(ISNUMBER(MATCH($F12,$C$42:$C$53,0)),INDEX($D$42:$D$53,MATCH($F12,$C$42:$C$53,0))," ")} -> 周围两圈 | H12: {=IF(ISNUMBER(MATCH($F12,$C$42:$C$53,0)),INDEX($E$42:$E$53,MATCH($F12,$C$42:$C$53,0))," ")} -> 攻击范围额外朝纵横四个方向延伸1格。
B13: =IF(VALUE($H$4)<2,"无","2") -> 2 | C13: 诱捕 | D13: 近战 | E13: 实体 | F13: 反击 | G13: {=IF(ISNUMBER(MATCH($F13,$C$42:$C$53,0)),INDEX($D$42:$D$53,MATCH($F13,$C$42:$C$53,0))," ")} -> 周围一圈 | H13: {=IF(ISNUMBER(MATCH($F13,$C$42:$C$53,0)),INDEX($E$42:$E$53,MATCH($F13,$C$42:$C$53,0))," ")} -> 被动：受到敌人攻击且对方处于该技能攻击范围内时触发，对其发动一次反击，并且伤害+2。
B14: =IF(VALUE($H4)<3,"无","3") -> 3 | C14: D-field | D14: 自动化 | E14: 光束 | F14: 守护 | G14: {=IF(ISNUMBER(MATCH($F14,$C$42:$C$53,0)),INDEX($D$42:$D$53,MATCH($F14,$C$42:$C$53,0))," ")} -> / | H14: {=IF(ISNUMBER(MATCH($F14,$C$42:$C$53,0)),INDEX($E$42:$E$53,MATCH($F14,$C$42:$C$53,0))," ")} -> 后续三次受到的伤害-5，与其他百分比减伤效果不叠加。
A15: 跟随 | B15: =IF(VALUE($H$5)<1,"无","1") -> 1 | C15: mega收束炮击 | D15: 远程 | E15: 光束 | F15: 稳定 | G15: {=IF(ISNUMBER(MATCH($F15,$C$42:$C$53,0)),INDEX($D$42:$D$53,MATCH($F15,$C$42:$C$53,0))," ")} -> 1~4格 | H15: {=IF(ISNUMBER(MATCH($F15,$C$42:$C$53,0)),INDEX($E$42:$E$53,MATCH($F15,$C$42:$C$53,0))," ")} -> 每局游戏一次，可以在移动后使用“专注射击”。
B16: =IF(VALUE($H$5)<2,"无","2") -> 2 | C16: mega扩散炮击 | D16: 远程 | E16: 光束 | F16: 扫射 | G16: {=IF(ISNUMBER(MATCH($F16,$C$42:$C$53,0)),INDEX($D$42:$D$53,MATCH($F16,$C$42:$C$53,0))," ")} -> 扇形2格 | H16: {=IF(ISNUMBER(MATCH($F16,$C$42:$C$53,0)),INDEX($E$42:$E$53,MATCH($F16,$C$42:$C$53,0))," ")} -> 不进行机动值判定，掷骰决定效果: 1~3：精准命中，单体攻击，但造成伤害-2。 4~6：对范围内的所有目标进行攻击，伤害由所有目标均摊。（目标数量可为1，友军同样作为目标）
A17: 右手 | B17: =IF(VALUE($H$6)<1,"无","1") -> 1 | C17: 有线式双发炮 | D17: 自动化 | E17: 光束 | F17: 助攻 | G17: {=IF(ISNUMBER(MATCH($F17,$C$42:$C$53,0)),INDEX($D$42:$D$53,MATCH($F17,$C$42:$C$53,0))," ")} -> / | H17: {=IF(ISNUMBER(MATCH($F17,$C$42:$C$53,0)),INDEX($E$42:$E$53,MATCH($F17,$C$42:$C$53,0))," ")} -> 后续五次造成的伤害+3（适用于反击）
B18: =IF(VALUE($H6)<2,"无","2") -> 无 | G18: {=IF(ISNUMBER(MATCH($F18,$C$42:$C$53,0)),INDEX($D$42:$D$53,MATCH($F18,$C$42:$C$53,0))," ")} | H18: {=IF(ISNUMBER(MATCH($F18,$C$42:$C$53,0)),INDEX($E$42:$E$53,MATCH($F18,$C$42:$C$53,0))," ")}
A19: 左手 | B19: =IF(VALUE($H$7)<1,"无","1") -> 1 | C19: 有线式双发炮 | D19: 自动化 | E19: 光束 | F19: 阻碍 | G19: {=IF(ISNUMBER(MATCH($F19,$C$42:$C$53,0)),INDEX($D$42:$D$53,MATCH($F19,$C$42:$C$53,0))," ")} -> / | H19: {=IF(ISNUMBER(MATCH($F19,$C$42:$C$53,0)),INDEX($E$42:$E$53,MATCH($F19,$C$42:$C$53,0))," ")} -> 在后续三次伤害计算中，对方的机动值-5。
B20: =IF(VALUE($H$7)<2,"无","2") -> 无 | G20: {=IF(ISNUMBER(MATCH($F20,$C$42:$C$53,0)),INDEX($D$42:$D$53,MATCH($F20,$C$42:$C$53,0))," ")} | H20: {=IF(ISNUMBER(MATCH($F20,$C$42:$C$53,0)),INDEX($E$42:$E$53,MATCH($F20,$C$42:$C$53,0))," ")}
A21: 其它 | B21: =IF(VALUE($H$8)<1,"无","1") -> 1 | C21: 移动补给单元 | D21: 近战 | F21: 补给（双槽） | G21: {=IF(ISNUMBER(MATCH($F21,$C$42:$C$53,0)),INDEX($D$42:$D$53,MATCH($F21,$C$42:$C$53,0))," ")} -> 周围一圈 | H21: {=IF(ISNUMBER(MATCH($F21,$C$42:$C$53,0)),INDEX($E$42:$E$53,MATCH($F21,$C$42:$C$53,0))," ")} -> （此技能占用两个技能槽）只能对友军单位使用，跳过移动环节，对范围1内的友军回复格斗值*1的hp
B22: =IF(VALUE($H8)<2,"无","2") -> 2 | C22: 移动补给单元 | D22: 近战 | F22: 补给（双槽） | G22: {=IF(ISNUMBER(MATCH($F22,$C$42:$C$53,0)),INDEX($D$42:$D$53,MATCH($F22,$C$42:$C$53,0))," ")} -> 周围一圈 | H22: {=IF(ISNUMBER(MATCH($F22,$C$42:$C$53,0)),INDEX($E$42:$E$53,MATCH($F22,$C$42:$C$53,0))," ")} -> （此技能占用两个技能槽）只能对友军单位使用，跳过移动环节，对范围1内的友军回复格斗值*1的hp
A23: 单位编号=单位号机体的可用技能，例：单位1=单位号为1的（机体/royroy/武器/防具/载具）的技能槽數量
A25: 表1·属性设计规范表
B26: 类型 | C26: 总点数（p） | D26: 分配项 | H26: 数值要求 | I26: 使用方式 | N26: 技能槽数量
A27: 1 | B27: 机体 | C27: 40 | D27: 格斗、射击、结构（*5=hp）、机动 | H27: —— | N27: 3
A28: 2 | B28: Royroy | C28: 25 | D28: 格斗、射击、结构（*3=hp）、机动 | H28: 任一项>=10 | I28: 1.消耗使用者的战术行动布置；2.始终跟随使用者周围1-3范围（坐标由使用者控制）； 3.布置到场上后可被指定为攻击目标。 | N28: 2
A29: 3 | B29: 武器 | C29: 15 | D29: 格斗、射击、结构（*1=耐久度）、机动 | H29: 结构>=1 | I29: 可携带出击/掉落/拾取 | N29: 1
A30: 4 | B30: 防具 | C30: 15 | D30: 格斗、射击、结构（*2=hp）、机动 | H30: 结构>=10 | I30: 每次抵消3点伤害， 溢出伤害由本体承伤， 耐久=5，归0后去除 | N30: 1
A31: 5 | B31: 载具 | C31: 15 | D31: 格斗、射击、结构（*1=耐久度）、机动 | H31: 机动>=10 | I31: 移动范围增加等同机动值距离， 被攻击时机动值判定+4，耐久度=可被攻击次数 | N31: 2
A32: 6 | B32: 背包 | C32: 10 | D32: 格斗、射击、结构（*2=HP）、机动 | H32: —— | I32: 仅出击时搭载，不可拾取，耐久度=5， 耐久度归零时相应加成消失， 恢复耐久度：回到出击点并成功消耗一个战术行动 | N32: 0
A34: 表2·技能属性面板数据表
B35: 技能类型 | C35: 属性选择 | D35: 攻击力计算方式 | H35: 可选效果（选1项）
A36: 1 | B36: 近战 | C36: 实体/光束 （二选一必选） | D36: 格斗数值点数+双方机动值差额（正负值） | H36: 反击 | I36: 格挡 | J36: 长柄 | K36: 补给（双槽） | L36: ——
A37: 2 | B37: 远程 | C37: 实体/光束 （二选一必选） | D37: 射击数值点数+双方机动值差额（正负值） | H37: 扫射 | I37: 投掷 | J37: 稳定 | K37: 狙击 | L37: ——
A38: 3 | B38: 自动化 | C38: 实体/光束 （二选一必选） | D38: 随效果条件触发 | H38: 助攻 | I38: 守护 | J38: 阻碍 | K38: 侦察（双槽） | L38: ——
A39: # | B39: 特殊加成 | C39: - | H39: 全覆式装甲 | I39: 抗性涂层 | J39: 变形
A41: 技能类型 | B41: 特性名称 | D41: 技能范围 | E41: 特性效果 | M41: 克制 | N41: 被克制
A42: 近战 | B42: 1 | C42: 反击 | D42: 周围一圈 | E42: 被动：受到敌人攻击且对方处于该技能攻击范围内时触发，对其发动一次反击，并且伤害+2。 | M42: 近战 | N42: 远程 | O42: =_xlfn.DISPIMG("ID_D8E47E93CE064B3EA8CA88044EB6FBCC",1) -> =DISPIMG("ID_D8E47E93CE064B3EA8CA88044EB6FBCC",1) | Q42: =_xlfn.DISPIMG("ID_00E30AD55BD4439088B9986D9A397D4F",1) -> =DISPIMG("ID_00E30AD55BD4439088B9986D9A397D4F",1) | S42: =_xlfn.DISPIMG("ID_B111B5C16B16432F8DF87944B2349F5A",1) -> =DISPIMG("ID_B111B5C16B16432F8DF87944B2349F5A",1)
B43: 2 | C43: 格挡 | D43: 周围一圈 | E43: 被动：受到敌人攻击时掷骰，1-3格挡失败，4-6本次受到的伤害-2。 | M43: - | N43: 格挡
...

Sheet 战斗规则
A1: 战斗机制 | L1: 结算检查&优先顺序 | O1: 1.当某一阶段发生多个条件时，按如下顺序依次计算。
A2: 基础 | B2: 行动流程 | C2: 回合开始 | D2: —— | E2: 移动行动 | F2: —— | G2: 战术行动 | H2: —— | I2: 结算2 | L2: 顺序 | M2: 回合开始 | N2: 移动行动 | O2: 声明战术 | P2: 选定目标 | Q2: 伤害值 | R2: 机动差值 | S2: 额外值 | T2: 结算1 | U2: 结算2
B3: 轮次 | C3: 以地联-拜隆-马克西翁的顺序行动，所有玩家都完成自己的回合行动为一个完整轮次。 | L3: 1 | M3: 空投 | N3: 援助 | O3: 技能选择 | P3: 指定目标 | Q3: 格斗 | R3: 基础机动值差 | S3: 防具抗性 | T3: 耐久度 | U3: 反击
B4: 回合 | C4: 玩家的回合可以先后执行两种行动， 1、移动行动。 2、战术行动。战术行动可以发起攻击，也可以使用自动化装备添加增益效果。 | L4: 2 | M4: 幸运 | N4: 单位移动 | O4: 侦察 | P4: 长柄 | Q4: 射击 | R4: 扫射 | S4: 扫射 | T4: 格挡 | U4: 抢夺
B5: 移动行动 | C5: 根据机体的移动范围进行移动或其它。 机体机动值=最大可移动格数， 斜向移动视为横移1+竖移1. | L5: 3 | M5: 火力覆盖 | N5: 防御单元 | O5: 补给 | P5: 扫射 | Q5: 决斗 | R5: 投掷 | S5: 投掷 | T5: 助攻 | U5: 斩杀
B6: 战术行动 | C6: 声明战术 | D6: 选定目标 | E6: 伤害值计算 | F6: 结算 | L6: 4 | M6: 迷雾系统 | N6: 专注射击 | O6: royroy | P6: 投掷 | Q6: 援助 | R6: 阻碍 | S6: 全覆式装甲 | T6: 守护
B7: 伤害值 | C7: （技能攻击力（格斗/射击）- 双方机动值差（正负值））+/- 额外数值（装甲/判定等）。 | L7: 5 | M7: 月面补给 | N7: 狙击 | P7: 奇袭 | Q7: 迷雾系统 | S7: 抗性涂层 | T7: 再动
B8: 空投 | C8: 第二轮开始，每轮由dm掷骰子，决定出现点数数量的武器或防具。同时随机生成坐标。 （如果坐标位有单位，则该单位回合开始时触发《幸运》） | L8: 6 | M8: 幸运 | N8: 补给 | P8: 援助 | Q8: 变形
B9: 防御单元 | C9: 1.防御单元拥有10hp。 2.计算距离时，一个单元格视作5格单元。 移动时不足以经过的在防御圈前一格停留。（攻击距离不足的则不可攻击） | J9: =_xlfn.DISPIMG("ID_EA67415A0995455ABF527BB2D12AD119",1) -> =DISPIMG("ID_EA67415A0995455ABF527BB2D12AD119",1) | L9: 7 | M9: 回复 | N9: 侦察 | Q9: 反击
B10: 强化防御 | C10: 1.横向相连的防御单元为1组，组间的防御单元hp累计计算。 2.击破后该组解除变成无属性区域。若组相邻的两组单元皆被击破，该组同样失效。 | J10: =_xlfn.DISPIMG("ID_A697753B0AB6431F9B3D49B29B266521",1) -> =DISPIMG("ID_A697753B0AB6431F9B3D49B29B266521",1) | L10: 8 | N10: 联防
B11: 基地 | C11: 1.拜隆军出生/补给点。 2.每次拜隆阵营单位回到基地，回复20hp，所携带的武器/防具等装备耐久度回复2 | J11: =_xlfn.DISPIMG("ID_06DC539B099E4035BF7E3FD9490B62B6",1) -> =DISPIMG("ID_06DC539B099E4035BF7E3FD9490B62B6",1) | L11: 计算区域
B12: 母舰 | C12: 1.地球联邦军出生/补给点。 2.每次地联阵营单位回到基地，回复20hp，所携带的武器/防具等装备耐久度回复2 | J12: =_xlfn.DISPIMG("ID_F7478FFE25464C8FA2A68F131E117822",1) -> =DISPIMG("ID_F7478FFE25464C8FA2A68F131E117822",1)
A13: 特殊词条 | K13: 发动阶段 | L13: 关联属性 | M13: 事件 | P13: 触发结果
A14: 攻击 | B14: 斩杀 | C14: 当近战武器攻击结算伤害后， 被攻击目标HP<5时可以掷骰一次： 点数>=剩余血量，被攻击目标被直接斩杀。 | K14: 结算2 | L14: 近战 | M14: 被攻击目标剩余血量<5 | P14: 被攻击目标HP <掷骰点数，则目标被直接斩杀。
B15: 决斗 | C15: 当攻击开始时，若双方均处于对方的攻击射程之内，且HP均低于对方对应格斗值或射击值中的最高值，则双方掷骰： 1.点数大者获胜。 2.点数相同视为同归于尽 | K15: 选定目标 | L15: - | M15: 双方均处于对方的攻击射程之内，且HP均低于对方对应格斗值或射击值中的最高值 | P15: 1.点数大者获胜。 2.点数相同视为同归于尽
B16: 抢夺 | C16: 若某一次伤害的值 > 被攻击者携带武器的攻击值，则攻击者可选择掷骰： 点数<4:抢夺失败； 点数>3:本次伤害减十，你获得该武器。 | K16: 结算 | L16: 武器 | M16: 伤害的值 > 被攻击者携带装备（武器）的攻击值 | P16: 点数<4:抢夺失败； 点数>3:本次伤害减半（向下取整），你获得该武器。
B17: 专注射击 | C17: 当玩家使用远程武器时，可以选择放弃本回合的移动行动，并在发起远程攻击时掷骰： 1-4点：本回合伤害+3； 5-6点：本回合伤害+5。 | K17: 移动行动 | L17: 远程 | M17: 放弃本回合的移动行动 | P17: 1-4点：本回合伤害+3； 5-6点：本回合伤害+5。
B18: 幸运 | C18: 当玩家获得空投时掷骰，根据结果获得： 1-2:跳过攻击，3-4：可以攻击，5-6：再次移动并攻击。 | K18: 移动行动 | L18: 空投 | M18: 获得空投时 | P18: 1-2:跳过攻击，3-4：可以攻击，5-6：再次移动并攻击。
B19: 再动 | C19: 被动：当玩家击杀一个敌军单位，可以再进行一个额外回合（即时生效，不能连续触发） | K19: 结算 | L19: - | M19: 击杀一个敌军单位 | P19: 再进行一个额外回合（即时生效，不能连续触发）
A20: 协同 | B20: 援助 | C20: 当玩家视距范围内的友军受到攻击，你可以放弃下一次你的回合中的一个行动，并获得以下效果： 1.放弃移动行动：你直接移动到攻击方与受击方之间的任意一格，并分担5点伤害； 2. 放弃战斗行动：你对敌方单位造成5点反击伤害。 | K20: 选定目标 | L20: 友军被选定 | M20: 视距范围内的友军受到攻击 | P20: 1.放弃移动行动：你直接移动到攻击方与受击方之间的任意一格，并分担5点伤害； 2. 放弃战斗行动：你对敌方单位造成5点反击伤害。
B21: 空投 | C21: 第二轮开始，每轮由dm掷骰子，决定出现点数数量的武器或防具。同时随机生成坐标。 （如果坐标位有单位，则该单位回合开始时触发《幸运》） | K21: 回合开始 | L21: 第二回合开始 | M21: 每轮由dm掷骰，根据点数确定生成随机的武器或防具数量。 | P21: 同时随机坐标。 （如果坐标位有单位，则该单位回合开始时触发《幸运》）
B22: 联防 | C22: 当三个同一阵营单位并列时， 非同一阵营单位不得直接穿越并列单位，需要绕行 | K22: 移动行动 | L22: 阵营 | M22: 当三个同一阵营单位并列 | P22: 非同一阵营单位不得直接穿越并列单位，需要绕行
B23: 抗性 | C23: 防具单位需要申明对于实体/光束武器的额外防御值， 如果受到的攻击与防具属性相同，结算时携带单位受到的伤害-2。 | K23: 额外值 | L23: 武器防具 | M23: 如果受到的攻击与防具属性相同 | P23: 结算时携带单位受到的伤害-2。
A25: 阵营特性 | L25: 地图特征
A26: 地球联合 | B26: 火力覆盖 | C26: 整场战斗中地联阵营可以选择适当的时机呼叫一次火力覆盖， 造成你们选择的格及周围3的范围内所有单位各5点伤害。（包括友军） | L26: 样式 | M26: 描述 | N26: 备注 | P26: 样式 | Q26: 描述 | R26: 备注
A27: =_xlfn.DISPIMG("ID_259C2484BD954135B1D132D1A8124B3C",1) -> =DISPIMG("ID_259C2484BD954135B1D132D1A8124B3C",1) | B27: 迷雾系统 | C27: 回合开始前掷点，点数=2:暴露所有隐藏单位坐标； 点数=4:呼叫视距范围内的友方单位协同攻击一次（每个地联回合只有一个单位限协同一次）。 | L27: =_xlfn.DISPIMG("ID_F7478FFE25464C8FA2A68F131E117822",1) -> =DISPIMG("ID_F7478FFE25464C8FA2A68F131E117822",1) | M27: 母舰 | N27: 地联出击点 | P27: =_xlfn.DISPIMG("ID_76191A7034294A2F8256380F1E832EB7",1) -> =DISPIMG("ID_76191A7034294A2F8256380F1E832EB7",1) | Q27: 月面 | R27: /
A28: 拜隆 | B28: 增援 | C28: 当拜隆单位受到攻击时，该单位四周1格范围内的友军可以进行增援，承受本次伤害（该伤害为80%）。 每次受到攻击时，最多仅有一名友军可以进行增援。 | L28: =_xlfn.DISPIMG("ID_A9639187B3144C57A2BE5AE757FE7972",1) -> =DISPIMG("ID_A9639187B3144C57A2BE5AE757FE7972",1) | M28: 太空 | N28: / | P28: =_xlfn.DISPIMG("ID_06DC539B099E4035BF7E3FD9490B62B6",1) -> =DISPIMG("ID_06DC539B099E4035BF7E3FD9490B62B6",1) | Q28: 基地 | R28: 基地内任意一格可能藏有核心
A29: =_xlfn.DISPIMG("ID_F61B406E8105401E828C43F4FA2F2B71",1) -> =DISPIMG("ID_F61B406E8105401E828C43F4FA2F2B71",1) | B29: 补给 | C29: 在本次作战中，拜隆军可以获得月面作战buff， 处于月面地形的拜隆阵营单位在回合开始回复4点HP。 | L29: =_xlfn.DISPIMG("ID_EA67415A0995455ABF527BB2D12AD119",1) -> =DISPIMG("ID_EA67415A0995455ABF527BB2D12AD119",1) | M29: 防御层 | N29: 距离1以外单位不能越过。 | P29: =_xlfn.DISPIMG("ID_A9639187B3144C57A2BE5AE757FE7972",1) -> =DISPIMG("ID_A9639187B3144C57A2BE5AE757FE7972",1) | Q29: 空投 | R29: 你进行一次掷点，点数>3获得装备
A30: 马克西翁 | B30: 奇袭 | C30: 可以在敌方攻击时选择跳过自己的下个回合，并选择如下一种发动： 1.顶替原本攻击方行动发动攻击（需要在自己的移动范围及攻击范围能覆盖到目标） 2.先于原攻击对原攻击方进攻并掷点： 点数为黑: 本次攻击的伤害值额外增加骰子点数的一半。（向上取整） 点数为红：你下次可移动的距离减少此骰子的点数值。
A31: =_xlfn.DISPIMG("ID_752A09597C4C41F5946A18E6374A90AC",1) -> =DISPIMG("ID_752A09597C4C41F5946A18E6374A90AC",1) | B31: 隐匿 | C31: 未攻击过的单位不可被敌军选中，除非玩家在敌方单位的扫描范围内。

Sheet 地图模拟
A1: {=IFERROR(INDEX($AL$2:$AL$18,MATCH(ADDRESS(ROW(),COLUMN(),4),$AM$2:$AM$18,0)),$AE$16)} -> =DISPIMG("ID_A9639187B3144C57A2BE5AE757FE7972",1) | B1: {=IFERROR(INDEX($AL$2:$AL$18,MATCH(ADDRESS(ROW(),COLUMN(),4),$AM$2:$AM$18,0)),$AE$16)} -> =DISPIMG("ID_A9639187B3144C57A2BE5AE757FE7972",1) | C1: {=IFERROR(INDEX($AL$2:$AL$18,MATCH(ADDRESS(ROW(),COLUMN(),4),$AM$2:$AM$18,0)),$AE$16)} -> =DISPIMG("ID_A9639187B3144C57A2BE5AE757FE7972",1) | D1: {=IFERROR(INDEX($AL$2:$AL$18,MATCH(ADDRESS(ROW(),COLUMN(),4),$AM$2:$AM$18,0)),$AE$16)} -> =DISPIMG("ID_A9639187B3144C57A2BE5AE757FE7972",1) | E1: {=IFERROR(INDEX($AL$2:$AL$18,MATCH(ADDRESS(ROW(),COLUMN(),4),$AM$2:$AM$18,0)),$AE$16)} -> =DISPIMG("ID_A9639187B3144C57A2BE5AE757FE7972",1) | F1: {=IFERROR(INDEX($AL$2:$AL$18,MATCH(ADDRESS(ROW(),COLUMN(),4),$AM$2:$AM$18,0)),$AE$16)} -> =DISPIMG("ID_A9639187B3144C57A2BE5AE757FE7972",1) | G1: {=IFERROR(INDEX($AL$2:$AL$18,MATCH(ADDRESS(ROW(),COLUMN(),4),$AM$2:$AM$18,0)),$AE$16)} -> =DISPIMG("ID_A9639187B3144C57A2BE5AE757FE7972",1) | H1: {=IFERROR(INDEX($AL$2:$AL$18,MATCH(ADDRESS(ROW(),COLUMN(),4),$AM$2:$AM$18,0)),$AE$16)} -> =DISPIMG("ID_A9639187B3144C57A2BE5AE757FE7972",1) | ... AD1: {=IFERROR(INDEX($AL$2:$AL$18,MATCH(ADDRESS(ROW(),COLUMN(),4),$AM$2:$AM$18,0)),$AE$16)} -> =DISPIMG("ID_A9639187B3144C57A2BE5AE757FE7972",1) | AE1: 刷新坐标点 | AJ1: =_xlfn.DISPIMG("ID_259C2484BD954135B1D132D1A8124B3C",1) -> =DISPIMG("ID_259C2484BD954135B1D132D1A8124B3C",1) | AK1: 代号 | AL1: 头像 | AM1: 目前坐标 | AN1: 剩余血量 | AO1: 格斗 | AP1: 射击 | AQ1: HP | AR1: 机动 | AT1: 跟随 | AU1: 右手 | AV1: 左手 | AW1: 其它
A2: {=IFERROR(INDEX($AL$2:$AL$18,MATCH(ADDRESS(ROW(),COLUMN(),4),$AM$2:$AM$18,0)),$AE$16)} -> =DISPIMG("ID_A9639187B3144C57A2BE5AE757FE7972",1) | B2: {=IFERROR(INDEX($AL$2:$AL$18,MATCH(ADDRESS(ROW(),COLUMN(),4),$AM$2:$AM$18,0)),$AE$16)} -> =DISPIMG("ID_A9639187B3144C57A2BE5AE757FE7972",1) | C2: {=IFERROR(INDEX($AL$2:$AL$18,MATCH(ADDRESS(ROW(),COLUMN(),4),$AM$2:$AM$18,0)),$AE$16)} -> =DISPIMG("ID_A9639187B3144C57A2BE5AE757FE7972",1) | D2: {=IFERROR(INDEX($AL$2:$AL$18,MATCH(ADDRESS(ROW(),COLUMN(),4),$AM$2:$AM$18,0)),$AE$16)} -> =DISPIMG("ID_A9639187B3144C57A2BE5AE757FE7972",1) | E2: {=IFERROR(INDEX($AL$2:$AL$18,MATCH(ADDRESS(ROW(),COLUMN(),4),$AM$2:$AM$18,0)),$AE$16)} -> =DISPIMG("ID_A9639187B3144C57A2BE5AE757FE7972",1) | F2: {=IFERROR(INDEX($AL$2:$AL$18,MATCH(ADDRESS(ROW(),COLUMN(),4),$AM$2:$AM$18,0)),$AE$16)} -> =DISPIMG("ID_A9639187B3144C57A2BE5AE757FE7972",1) | G2: {=IFERROR(INDEX($AL$2:$AL$18,MATCH(ADDRESS(ROW(),COLUMN(),4),$AM$2:$AM$18,0)),$AE$16)} -> =DISPIMG("ID_A9639187B3144C57A2BE5AE757FE7972",1) | H2: {=IFERROR(INDEX($AL$2:$AL$18,MATCH(ADDRESS(ROW(),COLUMN(),4),$AM$2:$AM$18,0)),$AE$16)} -> =DISPIMG("ID_A9639187B3144C57A2BE5AE757FE7972",1) | ... Q2: {=IFERROR(INDEX($AL$2:$AL$18,MATCH(ADDRESS(ROW(),COLUMN(),4),$AM$2:$AM$18,0)),$AE$16)} -> =DISPIMG("ID_A9639187B3144C57A2BE5AE757FE7972",1) | R2: {=IFERROR(INDEX($AL$2:$AL$18,MATCH(ADDRESS(ROW(),COLUMN(),4),$AM$2:$AM$18,0)),$AE$15)} -> =DISPIMG("ID_F7478FFE25464C8FA2A68F131E117822",1) | S2: {=IFERROR(INDEX($AL$2:$AL$18,MATCH(ADDRESS(ROW(),COLUMN(),4),$AM$2:$AM$18,0)),$AE$15)} -> =DISPIMG("ID_F7478FFE25464C8FA2A68F131E117822",1) | T2: {=IFERROR(INDEX($AL$2:$AL$18,MATCH(ADDRESS(ROW(),COLUMN(),4),$AM$2:$AM$18,0)),$AE$16)} -> =DISPIMG("ID_A9639187B3144C57A2BE5AE757FE7972",1) | U2: {=IFERROR(INDEX($AL$2:$AL$18,MATCH(ADDRESS(ROW(),COLUMN(),4),$AM$2:$AM$18,0)),$AE$16)} -> =DISPIMG("ID_A9639187B3144C57A2BE5AE757FE7972",1) | V2: {=IFERROR(INDEX($AL$2:$AL$18,MATCH(ADDRESS(ROW(),COLUMN(),4),$AM$2:$AM$18,0)),$AE$16)} -> =DISPIMG("ID_A9639187B3144C57A2BE5AE757FE7972",1) | W2: {=IFERROR(INDEX($AL$2:$AL$18,MATCH(ADDRESS(ROW(),COLUMN(),4),$AM$2:$AM$18,0)),$AE$16)} -> =DISPIMG("ID_A9639187B3144C57A2BE5AE757FE7972",1) | X2: {=IFERROR(INDEX($AL$2:$AL$18,MATCH(ADDRESS(ROW(),COLUMN(),4),$AM$2:$AM$18,0)),$AE$16)} -> =DISPIMG("ID_A9639187B3144C57A2BE5AE757FE7972",1) | Y2: {=IFERROR(INDEX($AL$2:$AL$18,MATCH(ADDRESS(ROW(),COLUMN(),4),$AM$2:$AM$18,0)),$AE$16)} -> =DISPIMG("ID_A9639187B3144C57A2BE5AE757FE7972",1) | Z2: {=IFERROR(INDEX($AL$2:$AL$18,MATCH(ADDRESS(ROW(),COLUMN(),4),$AM$2:$AM$18,0)),$AE$16)} -> =DISPIMG("ID_A9639187B3144C57A2BE5AE757FE7972",1) | AA2: {=IFERROR(INDEX($AL$2:$AL$18,MATCH(ADDRESS(ROW(),COLUMN(),4),$AM$2:$AM$18,0)),$AE$16)} -> =DISPIMG("ID_A9639187B3144C57A2BE5AE757FE7972",1) | ... AD2: {=IFERROR(INDEX($AL$2:$AL$18,MATCH(ADDRESS(ROW(),COLUMN(),4),$AM$2:$AM$18,0)),$AE$16)} -> =DISPIMG("ID_A9639187B3144C57A2BE5AE757FE7972",1) | AE2: 坐标 | AF2: =SUBSTITUTE(ADDRESS(1,RANDBETWEEN(1,30),4),"1","") -> R | AG2: =RANDBETWEEN(10,20) -> 18 | AJ2: 1 | AK2: A | AO2: =IFERROR([1]数据!B6,"") -> 0 | AP2: =IFERROR([1]数据!C6,"") -> 0 | AQ2: =IFERROR([1]数据!D6,"") -> 0 | AR2: =IFERROR([1]数据!E6,"") -> 0
A3: {=IFERROR(INDEX($AL$2:$AL$18,MATCH(ADDRESS(ROW(),COLUMN(),4),$AM$2:$AM$18,0)),$AE$16)} -> =DISPIMG("ID_A9639187B3144C57A2BE5AE757FE7972",1) | B3: {=IFERROR(INDEX($AL$2:$AL$18,MATCH(ADDRESS(ROW(),COLUMN(),4),$AM$2:$AM$18,0)),$AE$16)} -> =DISPIMG("ID_A9639187B3144C57A2BE5AE757FE7972",1) | C3: {=IFERROR(INDEX($AL$2:$AL$18,MATCH(ADDRESS(ROW(),COLUMN(),4),$AM$2:$AM$18,0)),$AE$16)} -> =DISPIMG("ID_A9639187B3144C57A2BE5AE757FE7972",1) | D3: {=IFERROR(INDEX($AL$2:$AL$18,MATCH(ADDRESS(ROW(),COLUMN(),4),$AM$2:$AM$18,0)),$AE$16)} -> =DISPIMG("ID_A9639187B3144C57A2BE5AE757FE7972",1) | E3: {=IFERROR(INDEX($AL$2:$AL$18,MATCH(ADDRESS(ROW(),COLUMN(),4),$AM$2:$AM$18,0)),$AE$16)} -> =DISPIMG("ID_A9639187B3144C57A2BE5AE757FE7972",1) | F3: {=IFERROR(INDEX($AL$2:$AL$18,MATCH(ADDRESS(ROW(),COLUMN(),4),$AM$2:$AM$18,0)),$AE$16)} -> =DISPIMG("ID_A9639187B3144C57A2BE5AE757FE7972",1) | G3: {=IFERROR(INDEX($AL$2:$AL$18,MATCH(ADDRESS(ROW(),COLUMN(),4),$AM$2:$AM$18,0)),$AE$16)} -> =DISPIMG("ID_A9639187B3144C57A2BE5AE757FE7972",1) | H3: {=IFERROR(INDEX($AL$2:$AL$18,MATCH(ADDRESS(ROW(),COLUMN(),4),$AM$2:$AM$18,0)),$AE$16)} -> =DISPIMG("ID_A9639187B3144C57A2BE5AE757FE7972",1) | ... Q3: {=IFERROR(INDEX($AL$2:$AL$18,MATCH(ADDRESS(ROW(),COLUMN(),4),$AM$2:$AM$18,0)),$AE$16)} -> =DISPIMG("ID_A9639187B3144C57A2BE5AE757FE7972",1) | R3: {=IFERROR(INDEX($AL$2:$AL$18,MATCH(ADDRESS(ROW(),COLUMN(),4),$AM$2:$AM$18,0)),$AE$15)} -> =DISPIMG("ID_F7478FFE25464C8FA2A68F131E117822",1) | S3: {=IFERROR(INDEX($AL$2:$AL$18,MATCH(ADDRESS(ROW(),COLUMN(),4),$AM$2:$AM$18,0)),$AE$15)} -> =DISPIMG("ID_F7478FFE25464C8FA2A68F131E117822",1) | T3: {=IFERROR(INDEX($AL$2:$AL$18,MATCH(ADDRESS(ROW(),COLUMN(),4),$AM$2:$AM$18,0)),$AE$16)} -> =DISPIMG("ID_A9639187B3144C57A2BE5AE757FE7972",1) | U3: {=IFERROR(INDEX($AL$2:$AL$18,MATCH(ADDRESS(ROW(),COLUMN(),4),$AM$2:$AM$18,0)),$AE$16)} -> =DISPIMG("ID_A9639187B3144C57A2BE5AE757FE7972",1) | V3: {=IFERROR(INDEX($AL$2:$AL$18,MATCH(ADDRESS(ROW(),COLUMN(),4),$AM$2:$AM$18,0)),$AE$16)} -> =DISPIMG("ID_A9639187B3144C57A2BE5AE757FE7972",1) | W3: {=IFERROR(INDEX($AL$2:$AL$18,MATCH(ADDRESS(ROW(),COLUMN(),4),$AM$2:$AM$18,0)),$AE$16)} -> =DISPIMG("ID_A9639187B3144C57A2BE5AE757FE7972",1) | X3: {=IFERROR(INDEX($AL$2:$AL$18,MATCH(ADDRESS(ROW(),COLUMN(),4),$AM$2:$AM$18,0)),$AE$16)} -> =DISPIMG("ID_A9639187B3144C57A2BE5AE757FE7972",1) | Y3: {=IFERROR(INDEX($AL$2:$AL$18,MATCH(ADDRESS(ROW(),COLUMN(),4),$AM$2:$AM$18,0)),$AE$16)} -> =DISPIMG("ID_A9639187B3144C57A2BE5AE757FE7972",1) | Z3: {=IFERROR(INDEX($AL$2:$AL$18,MATCH(ADDRESS(ROW(),COLUMN(),4),$AM$2:$AM$18,0)),$AE$16)} -> =DISPIMG("ID_A9639187B3144C57A2BE5AE757FE7972",1) | AA3: {=IFERROR(INDEX($AL$2:$AL$18,MATCH(ADDRESS(ROW(),COLUMN(),4),$AM$2:$AM$18,0)),$AE$16)} -> =DISPIMG("ID_A9639187B3144C57A2BE5AE757FE7972",1) | ... AD3: {=IFERROR(INDEX($AL$2:$AL$18,MATCH(ADDRESS(ROW(),COLUMN(),4),$AM$2:$AM$18,0)),$AE$16)} -> =DISPIMG("ID_A9639187B3144C57A2BE5AE757FE7972",1) | AE3: 坐标 | AF3: =SUBSTITUTE(ADDRESS(1,RANDBETWEEN(1,30),4),"1","") -> T | AG3: =RANDBETWEEN(10,20) -> 16 | AJ3: 2 | AK3: B | AO3: =IFERROR([1]数据!H6,"") -> 0 | AP3: =IFERROR([1]数据!I6,"") -> 0 | AQ3: =IFERROR([1]数据!J6,"") -> 0 | AR3: =IFERROR([1]数据!K6,"") -> 0
A4: {=IFERROR(INDEX($AL$2:$AL$18,MATCH(ADDRESS(ROW(),COLUMN(),4),$AM$2:$AM$18,0)),$AE$16)} -> =DISPIMG("ID_A9639187B3144C57A2BE5AE757FE7972",1) | B4: {=IFERROR(INDEX($AL$2:$AL$18,MATCH(ADDRESS(ROW(),COLUMN(),4),$AM$2:$AM$18,0)),$AE$16)} -> =DISPIMG("ID_A9639187B3144C57A2BE5AE757FE7972",1) | C4: {=IFERROR(INDEX($AL$2:$AL$18,MATCH(ADDRESS(ROW(),COLUMN(),4),$AM$2:$AM$18,0)),$AE$16)} -> =DISPIMG("ID_A9639187B3144C57A2BE5AE757FE7972",1) | D4: {=IFERROR(INDEX($AL$2:$AL$18,MATCH(ADDRESS(ROW(),COLUMN(),4),$AM$2:$AM$18,0)),$AE$16)} -> =DISPIMG("ID_A9639187B3144C57A2BE5AE757FE7972",1) | E4: {=IFERROR(INDEX($AL$2:$AL$18,MATCH(ADDRESS(ROW(),COLUMN(),4),$AM$2:$AM$18,0)),$AE$16)} -> =DISPIMG("ID_A9639187B3144C57A2BE5AE757FE7972",1) | F4: {=IFERROR(INDEX($AL$2:$AL$18,MATCH(ADDRESS(ROW(),COLUMN(),4),$AM$2:$AM$18,0)),$AE$16)} -> =DISPIMG("ID_A9639187B3144C57A2BE5AE757FE7972",1) | G4: {=IFERROR(INDEX($AL$2:$AL$18,MATCH(ADDRESS(ROW(),COLUMN(),4),$AM$2:$AM$18,0)),$AE$16)} -> =DISPIMG("ID_A9639187B3144C57A2BE5AE757FE7972",1) | H4: {=IFERROR(INDEX($AL$2:$AL$18,MATCH(ADDRESS(ROW(),COLUMN(),4),$AM$2:$AM$18,0)),$AE$16)} -> =DISPIMG("ID_A9639187B3144C57A2BE5AE757FE7972",1) | ... AD4: {=IFERROR(INDEX($AL$2:$AL$18,MATCH(ADDRESS(ROW(),COLUMN(),4),$AM$2:$AM$18,0)),$AE$16)} -> =DISPIMG("ID_A9639187B3144C57A2BE5AE757FE7972",1) | AE4: 坐标 | AF4: =SUBSTITUTE(ADDRESS(1,RANDBETWEEN(1,30),4),"1","") -> F | AG4: =RANDBETWEEN(10,20) -> 10 | AJ4: 3 | AK4: C | AO4: =IFERROR([1]数据!N6,"") -> 0 | AP4: =IFERROR([1]数据!O6,"") -> 0 | AQ4: =IFERROR([1]数据!P6,"") -> 0 | AR4: =IFERROR([1]数据!Q6,"") -> 0
A5: {=IFERROR(INDEX($AL$2:$AL$18,MATCH(ADDRESS(ROW(),COLUMN(),4),$AM$2:$AM$18,0)),$AE$16)} -> =DISPIMG("ID_A9639187B3144C57A2BE5AE757FE7972",1) | B5: {=IFERROR(INDEX($AL$2:$AL$18,MATCH(ADDRESS(ROW(),COLUMN(),4),$AM$2:$AM$18,0)),$AE$16)} -> =DISPIMG("ID_A9639187B3144C57A2BE5AE757FE7972",1) | C5: {=IFERROR(INDEX($AL$2:$AL$18,MATCH(ADDRESS(ROW(),COLUMN(),4),$AM$2:$AM$18,0)),$AE$16)} -> =DISPIMG("ID_A9639187B3144C57A2BE5AE757FE7972",1) | D5: {=IFERROR(INDEX($AL$2:$AL$18,MATCH(ADDRESS(ROW(),COLUMN(),4),$AM$2:$AM$18,0)),$AE$16)} -> =DISPIMG("ID_A9639187B3144C57A2BE5AE757FE7972",1) | E5: {=IFERROR(INDEX($AL$2:$AL$18,MATCH(ADDRESS(ROW(),COLUMN(),4),$AM$2:$AM$18,0)),$AE$16)} -> =DISPIMG("ID_A9639187B3144C57A2BE5AE757FE7972",1) | F5: {=IFERROR(INDEX($AL$2:$AL$18,MATCH(ADDRESS(ROW(),COLUMN(),4),$AM$2:$AM$18,0)),$AE$16)} -> =DISPIMG("ID_A9639187B3144C57A2BE5AE757FE7972",1) | G5: {=IFERROR(INDEX($AL$2:$AL$18,MATCH(ADDRESS(ROW(),COLUMN(),4),$AM$2:$AM$18,0)),$AE$16)} -> =DISPIMG("ID_A9639187B3144C57A2BE5AE757FE7972",1) | H5: {=IFERROR(INDEX($AL$2:$AL$18,MATCH(ADDRESS(ROW(),COLUMN(),4),$AM$2:$AM$18,0)),$AE$16)} -> =DISPIMG("ID_A9639187B3144C57A2BE5AE757FE7972",1) | ... AD5: {=IFERROR(INDEX($AL$2:$AL$18,MATCH(ADDRESS(ROW(),COLUMN(),4),$AM$2:$AM$18,0)),$AE$16)} -> =DISPIMG("ID_A9639187B3144C57A2BE5AE757FE7972",1) | AE5: 坐标 | AF5: =SUBSTITUTE(ADDRESS(1,RANDBETWEEN(1,30),4),"1","") -> Z | AG5: =RANDBETWEEN(10,20) -> 16 | AJ5: 4 | AK5: D | AO5: =IFERROR([1]数据!T6,"") -> 0 | AP5: =IFERROR([1]数据!U6,"") -> 0 | AQ5: =IFERROR([1]数据!V6,"") -> 0 | AR5: =IFERROR([1]数据!W6,"") -> 0
A6: {=IFERROR(INDEX($AL$2:$AL$18,MATCH(ADDRESS(ROW(),COLUMN(),4),$AM$2:$AM$18,0)),$AE$16)} -> =DISPIMG("ID_A9639187B3144C57A2BE5AE757FE7972",1) | B6: {=IFERROR(INDEX($AL$2:$AL$18,MATCH(ADDRESS(ROW(),COLUMN(),4),$AM$2:$AM$18,0)),$AE$16)} -> =DISPIMG("ID_A9639187B3144C57A2BE5AE757FE7972",1) | C6: {=IFERROR(INDEX($AL$2:$AL$18,MATCH(ADDRESS(ROW(),COLUMN(),4),$AM$2:$AM$18,0)),$AE$16)} -> =DISPIMG("ID_A9639187B3144C57A2BE5AE757FE7972",1) | D6: {=IFERROR(INDEX($AL$2:$AL$18,MATCH(ADDRESS(ROW(),COLUMN(),4),$AM$2:$AM$18,0)),$AE$16)} -> =DISPIMG("ID_A9639187B3144C57A2BE5AE757FE7972",1) | E6: {=IFERROR(INDEX($AL$2:$AL$18,MATCH(ADDRESS(ROW(),COLUMN(),4),$AM$2:$AM$18,0)),$AE$15)} -> =DISPIMG("ID_F7478FFE25464C8FA2A68F131E117822",1) | F6: {=IFERROR(INDEX($AL$2:$AL$18,MATCH(ADDRESS(ROW(),COLUMN(),4),$AM$2:$AM$18,0)),$AE$15)} -> =DISPIMG("ID_F7478FFE25464C8FA2A68F131E117822",1) | G6: {=IFERROR(INDEX($AL$2:$AL$18,MATCH(ADDRESS(ROW(),COLUMN(),4),$AM$2:$AM$18,0)),$AE$16)} -> =DISPIMG("ID_A9639187B3144C57A2BE5AE757FE7972",1) | H6: {=IFERROR(INDEX($AL$2:$AL$18,MATCH(ADDRESS(ROW(),COLUMN(),4),$AM$2:$AM$18,0)),$AE$16)} -> =DISPIMG("ID_A9639187B3144C57A2BE5AE757FE7972",1) | I6: {=IFERROR(INDEX($AL$2:$AL$18,MATCH(ADDRESS(ROW(),COLUMN(),4),$AM$2:$AM$18,0)),$AE$16)} -> =DISPIMG("ID_A9639187B3144C57A2BE5AE757FE7972",1) | J6: {=IFERROR(INDEX($AL$2:$AL$18,MATCH(ADDRESS(ROW(),COLUMN(),4),$AM$2:$AM$18,0)),$AE$16)} -> =DISPIMG("ID_A9639187B3144C57A2BE5AE757FE7972",1) | K6: {=IFERROR(INDEX($AL$2:$AL$18,MATCH(ADDRESS(ROW(),COLUMN(),4),$AM$2:$AM$18,0)),$AE$16)} -> =DISPIMG("ID_A9639187B3144C57A2BE5AE757FE7972",1) | L6: {=IFERROR(INDEX($AL$2:$AL$18,MATCH(ADDRESS(ROW(),COLUMN(),4),$AM$2:$AM$18,0)),$AE$16)} -> =DISPIMG("ID_A9639187B3144C57A2BE5AE757FE7972",1) | M6: {=IFERROR(INDEX($AL$2:$AL$18,MATCH(ADDRESS(ROW(),COLUMN(),4),$AM$2:$AM$18,0)),$AE$16)} -> =DISPIMG("ID_A9639187B3144C57A2BE5AE757FE7972",1) | N6: {=IFERROR(INDEX($AL$2:$AL$18,MATCH(ADDRESS(ROW(),COLUMN(),4),$AM$2:$AM$18,0)),$AE$16)} -> =DISPIMG("ID_A9639187B3144C57A2BE5AE757FE7972",1) | ... AD6: {=IFERROR(INDEX($AL$2:$AL$18,MATCH(ADDRESS(ROW(),COLUMN(),4),$AM$2:$AM$18,0)),$AE$16)} -> =DISPIMG("ID_A9639187B3144C57A2BE5AE757FE7972",1) | AE6: 坐标 | AF6: =SUBSTITUTE(ADDRESS(1,RANDBETWEEN(1,30),4),"1","") -> J | AG6: =RANDBETWEEN(10,20) -> 19 | AJ6: 5 | AK6: E | AO6: =IFERROR([1]数据!Z6,"") -> 0 | AP6: =IFERROR([1]数据!AA6,"") -> 0 | AQ6: =IFERROR([1]数据!AB6,"") -> 0 | AR6: =IFERROR([1]数据!AC6,"") -> 0
A7: {=IFERROR(INDEX($AL$2:$AL$18,MATCH(ADDRESS(ROW(),COLUMN(),4),$AM$2:$AM$18,0)),$AE$16)} -> =DISPIMG("ID_A9639187B3144C57A2BE5AE757FE7972",1) | B7: {=IFERROR(INDEX($AL$2:$AL$18,MATCH(ADDRESS(ROW(),COLUMN(),4),$AM$2:$AM$18,0)),$AE$16)} -> =DISPIMG("ID_A9639187B3144C57A2BE5AE757FE7972",1) | C7: {=IFERROR(INDEX($AL$2:$AL$18,MATCH(ADDRESS(ROW(),COLUMN(),4),$AM$2:$AM$18,0)),$AE$16)} -> =DISPIMG("ID_A9639187B3144C57A2BE5AE757FE7972",1) | D7: {=IFERROR(INDEX($AL$2:$AL$18,MATCH(ADDRESS(ROW(),COLUMN(),4),$AM$2:$AM$18,0)),$AE$16)} -> =DISPIMG("ID_A9639187B3144C57A2BE5AE757FE7972",1) | E7: {=IFERROR(INDEX($AL$2:$AL$18,MATCH(ADDRESS(ROW(),COLUMN(),4),$AM$2:$AM$18,0)),$AE$15)} -> =DISPIMG("ID_F7478FFE25464C8FA2A68F131E117822",1) | F7: {=IFERROR(INDEX($AL$2:$AL$18,MATCH(ADDRESS(ROW(),COLUMN(),4),$AM$2:$AM$18,0)),$AE$15)} -> =DISPIMG("ID_F7478FFE25464C8FA2A68F131E117822",1) | G7: {=IFERROR(INDEX($AL$2:$AL$18,MATCH(ADDRESS(ROW(),COLUMN(),4),$AM$2:$AM$18,0)),$AE$16)} -> =DISPIMG("ID_A9639187B3144C57A2BE5AE757FE7972",1) | H7: {=IFERROR(INDEX($AL$2:$AL$18,MATCH(ADDRESS(ROW(),COLUMN(),4),$AM$2:$AM$18,0)),$AE$16)} -> =DISPIMG("ID_A9639187B3144C57A2BE5AE757FE7972",1) | I7: {=IFERROR(INDEX($AL$2:$AL$18,MATCH(ADDRESS(ROW(),COLUMN(),4),$AM$2:$AM$18,0)),$AE$16)} -> =DISPIMG("ID_A9639187B3144C57A2BE5AE757FE7972",1) | J7: {=IFERROR(INDEX($AL$2:$AL$18,MATCH(ADDRESS(ROW(),COLUMN(),4),$AM$2:$AM$18,0)),$AE$16)} -> =DISPIMG("ID_A9639187B3144C57A2BE5AE757FE7972",1) | K7: {=IFERROR(INDEX($AL$2:$AL$18,MATCH(ADDRESS(ROW(),COLUMN(),4),$AM$2:$AM$18,0)),$AE$16)} -> =DISPIMG("ID_A9639187B3144C57A2BE5AE757FE7972",1) | L7: {=IFERROR(INDEX($AL$2:$AL$18,MATCH(ADDRESS(ROW(),COLUMN(),4),$AM$2:$AM$18,0)),$AE$16)} -> =DISPIMG("ID_A9639187B3144C57A2BE5AE757FE7972",1) | M7: {=IFERROR(INDEX($AL$2:$AL$18,MATCH(ADDRESS(ROW(),COLUMN(),4),$AM$2:$AM$18,0)),$AE$16)} -> =DISPIMG("ID_A9639187B3144C57A2BE5AE757FE7972",1) | N7: {=IFERROR(INDEX($AL$2:$AL$18,MATCH(ADDRESS(ROW(),COLUMN(),4),$AM$2:$AM$18,0)),$AE$16)} -> =DISPIMG("ID_A9639187B3144C57A2BE5AE757FE7972",1) | ... AD7: {=IFERROR(INDEX($AL$2:$AL$18,MATCH(ADDRESS(ROW(),COLUMN(),4),$AM$2:$AM$18,0)),$AE$16)} -> =DISPIMG("ID_A9639187B3144C57A2BE5AE757FE7972",1) | AE7: 坐标 | AF7: =SUBSTITUTE(ADDRESS(1,RANDBETWEEN(1,30),4),"1","") -> D | AG7: =RANDBETWEEN(10,20) -> 13 | AJ7: =_xlfn.DISPIMG("ID_F61B406E8105401E828C43F4FA2F2B71",1) -> =DISPIMG("ID_F61B406E8105401E828C43F4FA2F2B71",1) | AK7: 代号 | AL7: 头像 | AM7: 目前坐标 | AN7: 剩余血量 | AO7: 格斗 | AP7: 射击 | AQ7: HP | AR7: 机动 | AT7: 跟随 | AU7: 右手 | AV7: 左手 | AW7: 其它
A8: {=IFERROR(INDEX($AL$2:$AL$18,MATCH(ADDRESS(ROW(),COLUMN(),4),$AM$2:$AM$18,0)),$AE$16)} -> =DISPIMG("ID_A9639187B3144C57A2BE5AE757FE7972",1) | B8: {=IFERROR(INDEX($AL$2:$AL$18,MATCH(ADDRESS(ROW(),COLUMN(),4),$AM$2:$AM$18,0)),$AE$16)} -> =DISPIMG("ID_A9639187B3144C57A2BE5AE757FE7972",1) | C8: {=IFERROR(INDEX($AL$2:$AL$18,MATCH(ADDRESS(ROW(),COLUMN(),4),$AM$2:$AM$18,0)),$AE$16)} -> =DISPIMG("ID_A9639187B3144C57A2BE5AE757FE7972",1) | D8: {=IFERROR(INDEX($AL$2:$AL$18,MATCH(ADDRESS(ROW(),COLUMN(),4),$AM$2:$AM$18,0)),$AE$16)} -> =DISPIMG("ID_A9639187B3144C57A2BE5AE757FE7972",1) | E8: {=IFERROR(INDEX($AL$2:$AL$18,MATCH(ADDRESS(ROW(),COLUMN(),4),$AM$2:$AM$18,0)),$AE$16)} -> =DISPIMG("ID_A9639187B3144C57A2BE5AE757FE7972",1) | F8: {=IFERROR(INDEX($AL$2:$AL$18,MATCH(ADDRESS(ROW(),COLUMN(),4),$AM$2:$AM$18,0)),$AE$16)} -> =DISPIMG("ID_A9639187B3144C57A2BE5AE757FE7972",1) | G8: {=IFERROR(INDEX($AL$2:$AL$18,MATCH(ADDRESS(ROW(),COLUMN(),4),$AM$2:$AM$18,0)),$AE$16)} -> =DISPIMG("ID_A9639187B3144C57A2BE5AE757FE7972",1) | H8: {=IFERROR(INDEX($AL$2:$AL$18,MATCH(ADDRESS(ROW(),COLUMN(),4),$AM$2:$AM$18,0)),$AE$16)} -> =DISPIMG("ID_A9639187B3144C57A2BE5AE757FE7972",1) | ... AB8: {=IFERROR(INDEX($AL$2:$AL$18,MATCH(ADDRESS(ROW(),COLUMN(),4),$AM$2:$AM$18,0)),$AE$16)} -> =DISPIMG("ID_A9639187B3144C57A2BE5AE757FE7972",1) | AC8: {=IFERROR(INDEX($AL$2:$AL$18,MATCH(ADDRESS(ROW(),COLUMN(),4),$AM$2:$AM$18,0)),$AE$17)} -> =DISPIMG("ID_EA67415A0995455ABF527BB2D12AD119",1) | AD8: {=IFERROR(INDEX($AL$2:$AL$18,MATCH(ADDRESS(ROW(),COLUMN(),4),$AM$2:$AM$18,0)),$AE$17)} -> =DISPIMG("ID_EA67415A0995455ABF527BB2D12AD119",1) | AJ8: 1 | AK8: 甲 | AO8: =IFERROR([1]数据!B24,"") -> 0 | AP8: =IFERROR([1]数据!C24,"") -> 0 | AQ8: =IFERROR([1]数据!D24,"") -> 0 | AR8: =IFERROR([1]数据!E24,"") -> 0
A9: {=IFERROR(INDEX($AL$2:$AL$18,MATCH(ADDRESS(ROW(),COLUMN(),4),$AM$2:$AM$18,0)),$AE$16)} -> =DISPIMG("ID_A9639187B3144C57A2BE5AE757FE7972",1) | B9: {=IFERROR(INDEX($AL$2:$AL$18,MATCH(ADDRESS(ROW(),COLUMN(),4),$AM$2:$AM$18,0)),$AE$16)} -> =DISPIMG("ID_A9639187B3144C57A2BE5AE757FE7972",1) | C9: {=IFERROR(INDEX($AL$2:$AL$18,MATCH(ADDRESS(ROW(),COLUMN(),4),$AM$2:$AM$18,0)),$AE$16)} -> =DISPIMG("ID_A9639187B3144C57A2BE5AE757FE7972",1) | D9: {=IFERROR(INDEX($AL$2:$AL$18,MATCH(ADDRESS(ROW(),COLUMN(),4),$AM$2:$AM$18,0)),$AE$16)} -> =DISPIMG("ID_A9639187B3144C57A2BE5AE757FE7972",1) | E9: {=IFERROR(INDEX($AL$2:$AL$18,MATCH(ADDRESS(ROW(),COLUMN(),4),$AM$2:$AM$18,0)),$AE$16)} -> =DISPIMG("ID_A9639187B3144C57A2BE5AE757FE7972",1) | F9: {=IFERROR(INDEX($AL$2:$AL$18,MATCH(ADDRESS(ROW(),COLUMN(),4),$AM$2:$AM$18,0)),$AE$16)} -> =DISPIMG("ID_A9639187B3144C57A2BE5AE757FE7972",1) | G9: {=IFERROR(INDEX($AL$2:$AL$18,MATCH(ADDRESS(ROW(),COLUMN(),4),$AM$2:$AM$18,0)),$AE$16)} -> =DISPIMG("ID_A9639187B3144C57A2BE5AE757FE7972",1) | H9: {=IFERROR(INDEX($AL$2:$AL$18,MATCH(ADDRESS(ROW(),COLUMN(),4),$AM$2:$AM$18,0)),$AE$16)} -> =DISPIMG("ID_A9639187B3144C57A2BE5AE757FE7972",1) | ... X9: {=IFERROR(INDEX($AL$2:$AL$18,MATCH(ADDRESS(ROW(),COLUMN(),4),$AM$2:$AM$18,0)),$AE$16)} -> =DISPIMG("ID_A9639187B3144C57A2BE5AE757FE7972",1) | Y9: {=IFERROR(INDEX($AL$2:$AL$18,MATCH(ADDRESS(ROW(),COLUMN(),4),$AM$2:$AM$18,0)),$AE$17)} -> =DISPIMG("ID_EA67415A0995455ABF527BB2D12AD119",1) | Z9: {=IFERROR(INDEX($AL$2:$AL$18,MATCH(ADDRESS(ROW(),COLUMN(),4),$AM$2:$AM$18,0)),$AE$17)} -> =DISPIMG("ID_EA67415A0995455ABF527BB2D12AD119",1) | AA9: {=IFERROR(INDEX($AL$2:$AL$18,MATCH(ADDRESS(ROW(),COLUMN(),4),$AM$2:$AM$18,0)),$AE$17)} -> =DISPIMG("ID_EA67415A0995455ABF527BB2D12AD119",1) | AB9: {=IFERROR(INDEX($AL$2:$AL$18,MATCH(ADDRESS(ROW(),COLUMN(),4),$AM$2:$AM$18,0)),$AE$17)} -> =DISPIMG("ID_EA67415A0995455ABF527BB2D12AD119",1) | AC9: {=IFERROR(INDEX($AL$2:$AL$18,MATCH(ADDRESS(ROW(),COLUMN(),4),$AM$2:$AM$18,0)),$AE$18)} -> =DISPIMG("ID_76191A7034294A2F8256380F1E832EB7",1) | AD9: {=IFERROR(INDEX($AL$2:$AL$18,MATCH(ADDRESS(ROW(),COLUMN(),4),$AM$2:$AM$18,0)),$AE$18)} -> =DISPIMG("ID_76191A7034294A2F8256380F1E832EB7",1) | AJ9: 2 | AK9: 乙 | AO9: =IFERROR([1]数据!H24,"") -> 0 | AP9: =IFERROR([1]数据!I24,"") -> 0 | AQ9: =IFERROR([1]数据!J24,"") -> 0 | AR9: =IFERROR([1]数据!K24,"") -> 0
A10: {=IFERROR(INDEX($AL$2:$AL$18,MATCH(ADDRESS(ROW(),COLUMN(),4),$AM$2:$AM$18,0)),$AE$16)} -> =DISPIMG("ID_A9639187B3144C57A2BE5AE757FE7972",1) | B10: {=IFERROR(INDEX($AL$2:$AL$18,MATCH(ADDRESS(ROW(),COLUMN(),4),$AM$2:$AM$18,0)),$AE$16)} -> =DISPIMG("ID_A9639187B3144C57A2BE5AE757FE7972",1) | C10: {=IFERROR(INDEX($AL$2:$AL$18,MATCH(ADDRESS(ROW(),COLUMN(),4),$AM$2:$AM$18,0)),$AE$16)} -> =DISPIMG("ID_A9639187B3144C57A2BE5AE757FE7972",1) | D10: {=IFERROR(INDEX($AL$2:$AL$18,MATCH(ADDRESS(ROW(),COLUMN(),4),$AM$2:$AM$18,0)),$AE$16)} -> =DISPIMG("ID_A9639187B3144C57A2BE5AE757FE7972",1) | E10: {=IFERROR(INDEX($AL$2:$AL$18,MATCH(ADDRESS(ROW(),COLUMN(),4),$AM$2:$AM$18,0)),$AE$16)} -> =DISPIMG("ID_A9639187B3144C57A2BE5AE757FE7972",1) | F10: {=IFERROR(INDEX($AL$2:$AL$18,MATCH(ADDRESS(ROW(),COLUMN(),4),$AM$2:$AM$18,0)),$AE$16)} -> =DISPIMG("ID_A9639187B3144C57A2BE5AE757FE7972",1) | G10: {=IFERROR(INDEX($AL$2:$AL$18,MATCH(ADDRESS(ROW(),COLUMN(),4),$AM$2:$AM$18,0)),$AE$16)} -> =DISPIMG("ID_A9639187B3144C57A2BE5AE757FE7972",1) | H10: {=IFERROR(INDEX($AL$2:$AL$18,MATCH(ADDRESS(ROW(),COLUMN(),4),$AM$2:$AM$18,0)),$AE$16)} -> =DISPIMG("ID_A9639187B3144C57A2BE5AE757FE7972",1) | ... U10: {=IFERROR(INDEX($AL$2:$AL$18,MATCH(ADDRESS(ROW(),COLUMN(),4),$AM$2:$AM$18,0)),$AE$16)} -> =DISPIMG("ID_A9639187B3144C57A2BE5AE757FE7972",1) | V10: {=IFERROR(INDEX($AL$2:$AL$18,MATCH(ADDRESS(ROW(),COLUMN(),4),$AM$2:$AM$18,0)),$AE$17)} -> =DISPIMG("ID_EA67415A0995455ABF527BB2D12AD119",1) | W10: {=IFERROR(INDEX($AL$2:$AL$18,MATCH(ADDRESS(ROW(),COLUMN(),4),$AM$2:$AM$18,0)),$AE$17)} -> =DISPIMG("ID_EA67415A0995455ABF527BB2D12AD119",1) | X10: {=IFERROR(INDEX($AL$2:$AL$18,MATCH(ADDRESS(ROW(),COLUMN(),4),$AM$2:$AM$18,0)),$AE$17)} -> =DISPIMG("ID_EA67415A0995455ABF527BB2D12AD119",1) | Y10: {=IFERROR(INDEX($AL$2:$AL$18,MATCH(ADDRESS(ROW(),COLUMN(),4),$AM$2:$AM$18,0)),$AE$18)} -> =DISPIMG("ID_76191A7034294A2F8256380F1E832EB7",1) | Z10: {=IFERROR(INDEX($AL$2:$AL$18,MATCH(ADDRESS(ROW(),COLUMN(),4),$AM$2:$AM$18,0)),$AE$18)} -> =DISPIMG("ID_76191A7034294A2F8256380F1E832EB7",1) | AA10: {=IFERROR(INDEX($AL$2:$AL$18,MATCH(ADDRESS(ROW(),COLUMN(),4),$AM$2:$AM$18,0)),$AE$18)} -> =DISPIMG("ID_76191A7034294A2F8256380F1E832EB7",1) | AB10: {=IFERROR(INDEX($AL$2:$AL$18,MATCH(ADDRESS(ROW(),COLUMN(),4),$AM$2:$AM$18,0)),$AE$18)} -> =DISPIMG("ID_76191A7034294A2F8256380F1E832EB7",1) | AC10: {=IFERROR(INDEX($AL$2:$AL$18,MATCH(ADDRESS(ROW(),COLUMN(),4),$AM$2:$AM$18,0)),$AE$18)} -> =DISPIMG("ID_76191A7034294A2F8256380F1E832EB7",1) | AD10: {=IFERROR(INDEX($AL$2:$AL$18,MATCH(ADDRESS(ROW(),COLUMN(),4),$AM$2:$AM$18,0)),$AE$18)} -> =DISPIMG("ID_76191A7034294A2F8256380F1E832EB7",1) | AJ10: 3 | AK10: 丙 | AO10: =IFERROR([1]数据!N24,"") -> 0 | AP10: =IFERROR([1]数据!O24,"") -> 0 | AQ10: =IFERROR([1]数据!P24,"") -> 0 | AR10: =IFERROR([1]数据!Q24,"") -> 0
A11: {=IFERROR(INDEX($AL$2:$AL$18,MATCH(ADDRESS(ROW(),COLUMN(),4),$AM$2:$AM$18,0)),$AE$16)} -> =DISPIMG("ID_A9639187B3144C57A2BE5AE757FE7972",1) | B11: {=IFERROR(INDEX($AL$2:$AL$18,MATCH(ADDRESS(ROW(),COLUMN(),4),$AM$2:$AM$18,0)),$AE$16)} -> =DISPIMG("ID_A9639187B3144C57A2BE5AE757FE7972",1) | C11: {=IFERROR(INDEX($AL$2:$AL$18,MATCH(ADDRESS(ROW(),COLUMN(),4),$AM$2:$AM$18,0)),$AE$16)} -> =DISPIMG("ID_A9639187B3144C57A2BE5AE757FE7972",1) | D11: {=IFERROR(INDEX($AL$2:$AL$18,MATCH(ADDRESS(ROW(),COLUMN(),4),$AM$2:$AM$18,0)),$AE$16)} -> =DISPIMG("ID_A9639187B3144C57A2BE5AE757FE7972",1) | E11: {=IFERROR(INDEX($AL$2:$AL$18,MATCH(ADDRESS(ROW(),COLUMN(),4),$AM$2:$AM$18,0)),$AE$16)} -> =DISPIMG("ID_A9639187B3144C57A2BE5AE757FE7972",1) | F11: {=IFERROR(INDEX($AL$2:$AL$18,MATCH(ADDRESS(ROW(),COLUMN(),4),$AM$2:$AM$18,0)),$AE$16)} -> =DISPIMG("ID_A9639187B3144C57A2BE5AE757FE7972",1) | G11: {=IFERROR(INDEX($AL$2:$AL$18,MATCH(ADDRESS(ROW(),COLUMN(),4),$AM$2:$AM$18,0)),$AE$16)} -> =DISPIMG("ID_A9639187B3144C57A2BE5AE757FE7972",1) | H11: {=IFERROR(INDEX($AL$2:$AL$18,MATCH(ADDRESS(ROW(),COLUMN(),4),$AM$2:$AM$18,0)),$AE$16)} -> =DISPIMG("ID_A9639187B3144C57A2BE5AE757FE7972",1) | ... S11: {=IFERROR(INDEX($AL$2:$AL$18,MATCH(ADDRESS(ROW(),COLUMN(),4),$AM$2:$AM$18,0)),$AE$16)} -> =DISPIMG("ID_A9639187B3144C57A2BE5AE757FE7972",1) | T11: {=IFERROR(INDEX($AL$2:$AL$18,MATCH(ADDRESS(ROW(),COLUMN(),4),$AM$2:$AM$18,0)),$AE$17)} -> =DISPIMG("ID_EA67415A0995455ABF527BB2D12AD119",1) | U11: {=IFERROR(INDEX($AL$2:$AL$18,MATCH(ADDRESS(ROW(),COLUMN(),4),$AM$2:$AM$18,0)),$AE$17)} -> =DISPIMG("ID_EA67415A0995455ABF527BB2D12AD119",1) | V11: {=IFERROR(INDEX($AL$2:$AL$18,MATCH(ADDRESS(ROW(),COLUMN(),4),$AM$2:$AM$18,0)),$AE$18)} -> =DISPIMG("ID_76191A7034294A2F8256380F1E832EB7",1) | W11: {=IFERROR(INDEX($AL$2:$AL$18,MATCH(ADDRESS(ROW(),COLUMN(),4),$AM$2:$AM$18,0)),$AE$18)} -> =DISPIMG("ID_76191A7034294A2F8256380F1E832EB7",1) | X11: {=IFERROR(INDEX($AL$2:$AL$18,MATCH(ADDRESS(ROW(),COLUMN(),4),$AM$2:$AM$18,0)),$AE$18)} -> =DISPIMG("ID_76191A7034294A2F8256380F1E832EB7",1) | Y11: {=IFERROR(INDEX($AL$2:$AL$18,MATCH(ADDRESS(ROW(),COLUMN(),4),$AM$2:$AM$18,0)),$AE$18)} -> =DISPIMG("ID_76191A7034294A2F8256380F1E832EB7",1) | Z11: {=IFERROR(INDEX($AL$2:$AL$18,MATCH(ADDRESS(ROW(),COLUMN(),4),$AM$2:$AM$18,0)),$AE$18)} -> =DISPIMG("ID_76191A7034294A2F8256380F1E832EB7",1) | AA11: {=IFERROR(INDEX($AL$2:$AL$18,MATCH(ADDRESS(ROW(),COLUMN(),4),$AM$2:$AM$18,0)),$AE$18)} -> =DISPIMG("ID_76191A7034294A2F8256380F1E832EB7",1) | AB11: {=IFERROR(INDEX($AL$2:$AL$18,MATCH(ADDRESS(ROW(),COLUMN(),4),$AM$2:$AM$18,0)),$AE$18)} -> =DISPIMG("ID_76191A7034294A2F8256380F1E832EB7",1) | AC11: {=IFERROR(INDEX($AL$2:$AL$18,MATCH(ADDRESS(ROW(),COLUMN(),4),$AM$2:$AM$18,0)),$AE$18)} -> =DISPIMG("ID_76191A7034294A2F8256380F1E832EB7",1) | AD11: {=IFERROR(INDEX($AL$2:$AL$18,MATCH(ADDRESS(ROW(),COLUMN(),4),$AM$2:$AM$18,0)),$AE$18)} -> =DISPIMG("ID_76191A7034294A2F8256380F1E832EB7",1) | AJ11: 4 | AK11: 丁 | AO11: =IFERROR([1]数据!T24,"") -> 0 | AP11: =IFERROR([1]数据!U24,"") -> 0 | AQ11: =IFERROR([1]数据!V24,"") -> 0 | AR11: =IFERROR([1]数据!W24,"") -> 0
A12: {=IFERROR(INDEX($AL$2:$AL$18,MATCH(ADDRESS(ROW(),COLUMN(),4),$AM$2:$AM$18,0)),$AE$16)} -> =DISPIMG("ID_A9639187B3144C57A2BE5AE757FE7972",1) | B12: {=IFERROR(INDEX($AL$2:$AL$18,MATCH(ADDRESS(ROW(),COLUMN(),4),$AM$2:$AM$18,0)),$AE$16)} -> =DISPIMG("ID_A9639187B3144C57A2BE5AE757FE7972",1) | C12: {=IFERROR(INDEX($AL$2:$AL$18,MATCH(ADDRESS(ROW(),COLUMN(),4),$AM$2:$AM$18,0)),$AE$16)} -> =DISPIMG("ID_A9639187B3144C57A2BE5AE757FE7972",1) | D12: {=IFERROR(INDEX($AL$2:$AL$18,MATCH(ADDRESS(ROW(),COLUMN(),4),$AM$2:$AM$18,0)),$AE$16)} -> =DISPIMG("ID_A9639187B3144C57A2BE5AE757FE7972",1) | E12: {=IFERROR(INDEX($AL$2:$AL$18,MATCH(ADDRESS(ROW(),COLUMN(),4),$AM$2:$AM$18,0)),$AE$16)} -> =DISPIMG("ID_A9639187B3144C57A2BE5AE757FE7972",1) | F12: {=IFERROR(INDEX($AL$2:$AL$18,MATCH(ADDRESS(ROW(),COLUMN(),4),$AM$2:$AM$18,0)),$AE$16)} -> =DISPIMG("ID_A9639187B3144C57A2BE5AE757FE7972",1) | G12: {=IFERROR(INDEX($AL$2:$AL$18,MATCH(ADDRESS(ROW(),COLUMN(),4),$AM$2:$AM$18,0)),$AE$16)} -> =DISPIMG("ID_A9639187B3144C57A2BE5AE757FE7972",1) | H12: {=IFERROR(INDEX($AL$2:$AL$18,MATCH(ADDRESS(ROW(),COLUMN(),4),$AM$2:$AM$18,0)),$AE$16)} -> =DISPIMG("ID_A9639187B3144C57A2BE5AE757FE7972",1) | ... N12: {=IFERROR(INDEX($AL$2:$AL$18,MATCH(ADDRESS(ROW(),COLUMN(),4),$AM$2:$AM$18,0)),$AE$16)} -> =DISPIMG("ID_A9639187B3144C57A2BE5AE757FE7972",1) | O12: {=IFERROR(INDEX($AL$2:$AL$18,MATCH(ADDRESS(ROW(),COLUMN(),4),$AM$2:$AM$18,0)),$AE$17)} -> =DISPIMG("ID_EA67415A0995455ABF527BB2D12AD119",1) | P12: {=IFERROR(INDEX($AL$2:$AL$18,MATCH(ADDRESS(ROW(),COLUMN(),4),$AM$2:$AM$18,0)),$AE$17)} -> =DISPIMG("ID_EA67415A0995455ABF527BB2D12AD119",1) | Q12: {=IFERROR(INDEX($AL$2:$AL$18,MATCH(ADDRESS(ROW(),COLUMN(),4),$AM$2:$AM$18,0)),$AE$17)} -> =DISPIMG("ID_EA67415A0995455ABF527BB2D12AD119",1) | R12: {=IFERROR(INDEX($AL$2:$AL$18,MATCH(ADDRESS(ROW(),COLUMN(),4),$AM$2:$AM$18,0)),$AE$17)} -> =DISPIMG("ID_EA67415A0995455ABF527BB2D12AD119",1) | S12: {=IFERROR(INDEX($AL$2:$AL$18,MATCH(ADDRESS(ROW(),COLUMN(),4),$AM$2:$AM$18,0)),$AE$17)} -> =DISPIMG("ID_EA67415A0995455ABF527BB2D12AD119",1) | T12: {=IFERROR(INDEX($AL$2:$AL$18,MATCH(ADDRESS(ROW(),COLUMN(),4),$AM$2:$AM$18,0)),$AE$18)} -> =DISPIMG("ID_76191A7034294A2F8256380F1E832EB7",1) | U12: {=IFERROR(INDEX($AL$2:$AL$18,MATCH(ADDRESS(ROW(),COLUMN(),4),$AM$2:$AM$18,0)),$AE$18)} -> =DISPIMG("ID_76191A7034294A2F8256380F1E832EB7",1) | V12: {=IFERROR(INDEX($AL$2:$AL$18,MATCH(ADDRESS(ROW(),COLUMN(),4),$AM$2:$AM$18,0)),$AE$18)} -> =DISPIMG("ID_76191A7034294A2F8256380F1E832EB7",1) | W12: {=IFERROR(INDEX($AL$2:$AL$18,MATCH(ADDRESS(ROW(),COLUMN(),4),$AM$2:$AM$18,0)),$AE$18)} -> =DISPIMG("ID_76191A7034294A2F8256380F1E832EB7",1) | X12: {=IFERROR(INDEX($AL$2:$AL$18,MATCH(ADDRESS(ROW(),COLUMN(),4),$AM$2:$AM$18,0)),$AE$18)} -> =DISPIMG("ID_76191A7034294A2F8256380F1E832EB7",1) | Y12: {=IFERROR(INDEX($AL$2:$AL$18,MATCH(ADDRESS(ROW(),COLUMN(),4),$AM$2:$AM$18,0)),$AE$18)} -> =DISPIMG("ID_76191A7034294A2F8256380F1E832EB7",1) | Z12: {=IFERROR(INDEX($AL$2:$AL$18,MATCH(ADDRESS(ROW(),COLUMN(),4),$AM$2:$AM$18,0)),$AE$18)} -> =DISPIMG("ID_76191A7034294A2F8256380F1E832EB7",1) | AA12: {=IFERROR(INDEX($AL$2:$AL$18,MATCH(ADDRESS(ROW(),COLUMN(),4),$AM$2:$AM$18,0)),$AE$18)} -> =DISPIMG("ID_76191A7034294A2F8256380F1E832EB7",1) | ... AD12: {=IFERROR(INDEX($AL$2:$AL$18,MATCH(ADDRESS(ROW(),COLUMN(),4),$AM$2:$AM$18,0)),$AE$18)} -> =DISPIMG("ID_76191A7034294A2F8256380F1E832EB7",1) | AJ12: 5 | AK12: 子 | AO12: =IFERROR([1]数据!Z24,"") -> 0 | AP12: =IFERROR([1]数据!AA24,"") -> 0 | AQ12: =IFERROR([1]数据!AB24,"") -> 0 | AR12: =IFERROR([1]数据!AC24,"") -> 0
A13: {=IFERROR(INDEX($AL$2:$AL$18,MATCH(ADDRESS(ROW(),COLUMN(),4),$AM$2:$AM$18,0)),$AE$16)} -> =DISPIMG("ID_A9639187B3144C57A2BE5AE757FE7972",1) | B13: {=IFERROR(INDEX($AL$2:$AL$18,MATCH(ADDRESS(ROW(),COLUMN(),4),$AM$2:$AM$18,0)),$AE$16)} -> =DISPIMG("ID_A9639187B3144C57A2BE5AE757FE7972",1) | C13: {=IFERROR(INDEX($AL$2:$AL$18,MATCH(ADDRESS(ROW(),COLUMN(),4),$AM$2:$AM$18,0)),$AE$16)} -> =DISPIMG("ID_A9639187B3144C57A2BE5AE757FE7972",1) | D13: {=IFERROR(INDEX($AL$2:$AL$18,MATCH(ADDRESS(ROW(),COLUMN(),4),$AM$2:$AM$18,0)),$AE$16)} -> =DISPIMG("ID_A9639187B3144C57A2BE5AE757FE7972",1) | E13: {=IFERROR(INDEX($AL$2:$AL$18,MATCH(ADDRESS(ROW(),COLUMN(),4),$AM$2:$AM$18,0)),$AE$16)} -> =DISPIMG("ID_A9639187B3144C57A2BE5AE757FE7972",1) | F13: {=IFERROR(INDEX($AL$2:$AL$18,MATCH(ADDRESS(ROW(),COLUMN(),4),$AM$2:$AM$18,0)),$AE$16)} -> =DISPIMG("ID_A9639187B3144C57A2BE5AE757FE7972",1) | G13: {=IFERROR(INDEX($AL$2:$AL$18,MATCH(ADDRESS(ROW(),COLUMN(),4),$AM$2:$AM$18,0)),$AE$16)} -> =DISPIMG("ID_A9639187B3144C57A2BE5AE757FE7972",1) | H13: {=IFERROR(INDEX($AL$2:$AL$18,MATCH(ADDRESS(ROW(),COLUMN(),4),$AM$2:$AM$18,0)),$AE$16)} -> =DISPIMG("ID_A9639187B3144C57A2BE5AE757FE7972",1) | ... K13: {=IFERROR(INDEX($AL$2:$AL$18,MATCH(ADDRESS(ROW(),COLUMN(),4),$AM$2:$AM$18,0)),$AE$16)} -> =DISPIMG("ID_A9639187B3144C57A2BE5AE757FE7972",1) | L13: {=IFERROR(INDEX($AL$2:$AL$18,MATCH(ADDRESS(ROW(),COLUMN(),4),$AM$2:$AM$18,0)),$AE$17)} -> =DISPIMG("ID_EA67415A0995455ABF527BB2D12AD119",1) | M13: {=IFERROR(INDEX($AL$2:$AL$18,MATCH(ADDRESS(ROW(),COLUMN(),4),$AM$2:$AM$18,0)),$AE$17)} -> =DISPIMG("ID_EA67415A0995455ABF527BB2D12AD119",1) | N13: {=IFERROR(INDEX($AL$2:$AL$18,MATCH(ADDRESS(ROW(),COLUMN(),4),$AM$2:$AM$18,0)),$AE$17)} -> =DISPIMG("ID_EA67415A0995455ABF527BB2D12AD119",1) | O13: {=IFERROR(INDEX($AL$2:$AL$18,MATCH(ADDRESS(ROW(),COLUMN(),4),$AM$2:$AM$18,0)),$AE$18)} -> =DISPIMG("ID_76191A7034294A2F8256380F1E832EB7",1) | P13: {=IFERROR(INDEX($AL$2:$AL$18,MATCH(ADDRESS(ROW(),COLUMN(),4),$AM$2:$AM$18,0)),$AE$18)} -> =DISPIMG("ID_76191A7034294A2F8256380F1E832EB7",1) | Q13: {=IFERROR(INDEX($AL$2:$AL$18,MATCH(ADDRESS(ROW(),COLUMN(),4),$AM$2:$AM$18,0)),$AE$18)} -> =DISPIMG("ID_76191A7034294A2F8256380F1E832EB7",1) | R13: {=IFERROR(INDEX($AL$2:$AL$18,MATCH(ADDRESS(ROW(),COLUMN(),4),$AM$2:$AM$18,0)),$AE$18)} -> =DISPIMG("ID_76191A7034294A2F8256380F1E832EB7",1) | S13: {=IFERROR(INDEX($AL$2:$AL$18,MATCH(ADDRESS(ROW(),COLUMN(),4),$AM$2:$AM$18,0)),$AE$18)} -> =DISPIMG("ID_76191A7034294A2F8256380F1E832EB7",1) | T13: {=IFERROR(INDEX($AL$2:$AL$18,MATCH(ADDRESS(ROW(),COLUMN(),4),$AM$2:$AM$18,0)),$AE$18)} -> =DISPIMG("ID_76191A7034294A2F8256380F1E832EB7",1) | U13: {=IFERROR(INDEX($AL$2:$AL$18,MATCH(ADDRESS(ROW(),COLUMN(),4),$AM$2:$AM$18,0)),$AE$18)} -> =DISPIMG("ID_76191A7034294A2F8256380F1E832EB7",1) | V13: {=IFERROR(INDEX($AL$2:$AL$18,MATCH(ADDRESS(ROW(),COLUMN(),4),$AM$2:$AM$18,0)),$AE$18)} -> =DISPIMG("ID_76191A7034294A2F8256380F1E832EB7",1) | ... AD13: {=IFERROR(INDEX($AL$2:$AL$18,MATCH(ADDRESS(ROW(),COLUMN(),4),$AM$2:$AM$18,0)),$AE$18)} -> =DISPIMG("ID_76191A7034294A2F8256380F1E832EB7",1) | AJ13: =_xlfn.DISPIMG("ID_752A09597C4C41F5946A18E6374A90AC",1) -> =DISPIMG("ID_752A09597C4C41F5946A18E6374A90AC",1) | AK13: 代号 | AL13: 头像 | AM13: 目前坐标 | AN13: 剩余血量 | AO13: 格斗 | AP13: 射击 | AQ13: HP | AR13: 机动 | AT13: 跟随 | AU13: 右手 | AV13: 左手 | AW13: 其它
A14: {=IFERROR(INDEX($AL$2:$AL$18,MATCH(ADDRESS(ROW(),COLUMN(),4),$AM$2:$AM$18,0)),$AE$16)} -> =DISPIMG("ID_A9639187B3144C57A2BE5AE757FE7972",1) | B14: {=IFERROR(INDEX($AL$2:$AL$18,MATCH(ADDRESS(ROW(),COLUMN(),4),$AM$2:$AM$18,0)),$AE$16)} -> =DISPIMG("ID_A9639187B3144C57A2BE5AE757FE7972",1) | C14: {=IFERROR(INDEX($AL$2:$AL$18,MATCH(ADDRESS(ROW(),COLUMN(),4),$AM$2:$AM$18,0)),$AE$16)} -> =DISPIMG("ID_A9639187B3144C57A2BE5AE757FE7972",1) | D14: {=IFERROR(INDEX($AL$2:$AL$18,MATCH(ADDRESS(ROW(),COLUMN(),4),$AM$2:$AM$18,0)),$AE$16)} -> =DISPIMG("ID_A9639187B3144C57A2BE5AE757FE7972",1) | E14: {=IFERROR(INDEX($AL$2:$AL$18,MATCH(ADDRESS(ROW(),COLUMN(),4),$AM$2:$AM$18,0)),$AE$16)} -> =DISPIMG("ID_A9639187B3144C57A2BE5AE757FE7972",1) | F14: {=IFERROR(INDEX($AL$2:$AL$18,MATCH(ADDRESS(ROW(),COLUMN(),4),$AM$2:$AM$18,0)),$AE$16)} -> =DISPIMG("ID_A9639187B3144C57A2BE5AE757FE7972",1) | G14: {=IFERROR(INDEX($AL$2:$AL$18,MATCH(ADDRESS(ROW(),COLUMN(),4),$AM$2:$AM$18,0)),$AE$16)} -> =DISPIMG("ID_A9639187B3144C57A2BE5AE757FE7972",1) | H14: {=IFERROR(INDEX($AL$2:$AL$18,MATCH(ADDRESS(ROW(),COLUMN(),4),$AM$2:$AM$18,0)),$AE$16)} -> =DISPIMG("ID_A9639187B3144C57A2BE5AE757FE7972",1) | I14: {=IFERROR(INDEX($AL$2:$AL$18,MATCH(ADDRESS(ROW(),COLUMN(),4),$AM$2:$AM$18,0)),$AE$16)} -> =DISPIMG("ID_A9639187B3144C57A2BE5AE757FE7972",1) | J14: {=IFERROR(INDEX($AL$2:$AL$18,MATCH(ADDRESS(ROW(),COLUMN(),4),$AM$2:$AM$18,0)),$AE$17)} -> =DISPIMG("ID_EA67415A0995455ABF527BB2D12AD119",1) | K14: {=IFERROR(INDEX($AL$2:$AL$18,MATCH(ADDRESS(ROW(),COLUMN(),4),$AM$2:$AM$18,0)),$AE$17)} -> =DISPIMG("ID_EA67415A0995455ABF527BB2D12AD119",1) | L14: {=IFERROR(INDEX($AL$2:$AL$18,MATCH(ADDRESS(ROW(),COLUMN(),4),$AM$2:$AM$18,0)),$AE$18)} -> =DISPIMG("ID_76191A7034294A2F8256380F1E832EB7",1) | M14: {=IFERROR(INDEX($AL$2:$AL$18,MATCH(ADDRESS(ROW(),COLUMN(),4),$AM$2:$AM$18,0)),$AE$18)} -> =DISPIMG("ID_76191A7034294A2F8256380F1E832EB7",1) | N14: {=IFERROR(INDEX($AL$2:$AL$18,MATCH(ADDRESS(ROW(),COLUMN(),4),$AM$2:$AM$18,0)),$AE$18)} -> =DISPIMG("ID_76191A7034294A2F8256380F1E832EB7",1) | O14: {=IFERROR(INDEX($AL$2:$AL$18,MATCH(ADDRESS(ROW(),COLUMN(),4),$AM$2:$AM$18,0)),$AE$18)} -> =DISPIMG("ID_76191A7034294A2F8256380F1E832EB7",1) | P14: {=IFERROR(INDEX($AL$2:$AL$18,MATCH(ADDRESS(ROW(),COLUMN(),4),$AM$2:$AM$18,0)),$AE$18)} -> =DISPIMG("ID_76191A7034294A2F8256380F1E832EB7",1) | Q14: {=IFERROR(INDEX($AL$2:$AL$18,MATCH(ADDRESS(ROW(),COLUMN(),4),$AM$2:$AM$18,0)),$AE$18)} -> =DISPIMG("ID_76191A7034294A2F8256380F1E832EB7",1) | R14: {=IFERROR(INDEX($AL$2:$AL$18,MATCH(ADDRESS(ROW(),COLUMN(),4),$AM$2:$AM$18,0)),$AE$18)} -> =DISPIMG("ID_76191A7034294A2F8256380F1E832EB7",1) | S14: {=IFERROR(INDEX($AL$2:$AL$18,MATCH(ADDRESS(ROW(),COLUMN(),4),$AM$2:$AM$18,0)),$AE$18)} -> =DISPIMG("ID_76191A7034294A2F8256380F1E832EB7",1) | ... AD14: {=IFERROR(INDEX($AL$2:$AL$18,MATCH(ADDRESS(ROW(),COLUMN(),4),$AM$2:$AM$18,0)),$AE$18)} -> =DISPIMG("ID_76191A7034294A2F8256380F1E832EB7",1) | AE14: 样式 | AF14: 描述 | AG14: 备注 | AJ14: 1 | AK14: 一 | AO14: =IFERROR([1]数据!B42,"") -> 0 | AP14: =IFERROR([1]数据!C42,"") -> 0 | AQ14: =IFERROR([1]数据!D42,"") -> 0 | AR14: =IFERROR([1]数据!E42,"") -> 0
A15: {=IFERROR(INDEX($AL$2:$AL$18,MATCH(ADDRESS(ROW(),COLUMN(),4),$AM$2:$AM$18,0)),$AE$16)} -> =DISPIMG("ID_A9639187B3144C57A2BE5AE757FE7972",1) | B15: {=IFERROR(INDEX($AL$2:$AL$18,MATCH(ADDRESS(ROW(),COLUMN(),4),$AM$2:$AM$18,0)),$AE$16)} -> =DISPIMG("ID_A9639187B3144C57A2BE5AE757FE7972",1) | C15: {=IFERROR(INDEX($AL$2:$AL$18,MATCH(ADDRESS(ROW(),COLUMN(),4),$AM$2:$AM$18,0)),$AE$16)} -> =DISPIMG("ID_A9639187B3144C57A2BE5AE757FE7972",1) | D15: {=IFERROR(INDEX($AL$2:$AL$18,MATCH(ADDRESS(ROW(),COLUMN(),4),$AM$2:$AM$18,0)),$AE$16)} -> =DISPIMG("ID_A9639187B3144C57A2BE5AE757FE7972",1) | E15: {=IFERROR(INDEX($AL$2:$AL$18,MATCH(ADDRESS(ROW(),COLUMN(),4),$AM$2:$AM$18,0)),$AE$16)} -> =DISPIMG("ID_A9639187B3144C57A2BE5AE757FE7972",1) | F15: {=IFERROR(INDEX($AL$2:$AL$18,MATCH(ADDRESS(ROW(),COLUMN(),4),$AM$2:$AM$18,0)),$AE$16)} -> =DISPIMG("ID_A9639187B3144C57A2BE5AE757FE7972",1) | G15: {=IFERROR(INDEX($AL$2:$AL$18,MATCH(ADDRESS(ROW(),COLUMN(),4),$AM$2:$AM$18,0)),$AE$17)} -> =DISPIMG("ID_EA67415A0995455ABF527BB2D12AD119",1) | H15: {=IFERROR(INDEX($AL$2:$AL$18,MATCH(ADDRESS(ROW(),COLUMN(),4),$AM$2:$AM$18,0)),$AE$17)} -> =DISPIMG("ID_EA67415A0995455ABF527BB2D12AD119",1) | I15: {=IFERROR(INDEX($AL$2:$AL$18,MATCH(ADDRESS(ROW(),COLUMN(),4),$AM$2:$AM$18,0)),$AE$17)} -> =DISPIMG("ID_EA67415A0995455ABF527BB2D12AD119",1) | J15: {=IFERROR(INDEX($AL$2:$AL$18,MATCH(ADDRESS(ROW(),COLUMN(),4),$AM$2:$AM$18,0)),$AE$18)} -> =DISPIMG("ID_76191A7034294A2F8256380F1E832EB7",1) | K15: {=IFERROR(INDEX($AL$2:$AL$18,MATCH(ADDRESS(ROW(),COLUMN(),4),$AM$2:$AM$18,0)),$AE$18)} -> =DISPIMG("ID_76191A7034294A2F8256380F1E832EB7",1) | L15: {=IFERROR(INDEX($AL$2:$AL$18,MATCH(ADDRESS(ROW(),COLUMN(),4),$AM$2:$AM$18,0)),$AE$18)} -> =DISPIMG("ID_76191A7034294A2F8256380F1E832EB7",1) | M15: {=IFERROR(INDEX($AL$2:$AL$18,MATCH(ADDRESS(ROW(),COLUMN(),4),$AM$2:$AM$18,0)),$AE$18)} -> =DISPIMG("ID_76191A7034294A2F8256380F1E832EB7",1) | N15: {=IFERROR(INDEX($AL$2:$AL$18,MATCH(ADDRESS(ROW(),COLUMN(),4),$AM$2:$AM$18,0)),$AE$18)} -> =DISPIMG("ID_76191A7034294A2F8256380F1E832EB7",1) | O15: {=IFERROR(INDEX($AL$2:$AL$18,MATCH(ADDRESS(ROW(),COLUMN(),4),$AM$2:$AM$18,0)),$AE$18)} -> =DISPIMG("ID_76191A7034294A2F8256380F1E832EB7",1) | P15: {=IFERROR(INDEX($AL$2:$AL$18,MATCH(ADDRESS(ROW(),COLUMN(),4),$AM$2:$AM$18,0)),$AE$18)} -> =DISPIMG("ID_76191A7034294A2F8256380F1E832EB7",1) | Q15: {=IFERROR(INDEX($AL$2:$AL$18,MATCH(ADDRESS(ROW(),COLUMN(),4),$AM$2:$AM$18,0)),$AE$18)} -> =DISPIMG("ID_76191A7034294A2F8256380F1E832EB7",1) | ... AD15: {=IFERROR(INDEX($AL$2:$AL$18,MATCH(ADDRESS(ROW(),COLUMN(),4),$AM$2:$AM$18,0)),$AE$18)} -> =DISPIMG("ID_76191A7034294A2F8256380F1E832EB7",1) | AE15: =_xlfn.DISPIMG("ID_F7478FFE25464C8FA2A68F131E117822",1) -> =DISPIMG("ID_F7478FFE25464C8FA2A68F131E117822",1) | AF15: 母舰 | AG15: 地联出击点 | AJ15: 2 | AK15: 二 | AO15: =IFERROR([1]数据!H42,"") -> 0 | AP15: =IFERROR([1]数据!I42,"") -> 0 | AQ15: =IFERROR([1]数据!J42,"") -> 0 | AR15: =IFERROR([1]数据!K42,"") -> 0
A16: {=IFERROR(INDEX($AL$2:$AL$18,MATCH(ADDRESS(ROW(),COLUMN(),4),$AM$2:$AM$18,0)),$AE$16)} -> =DISPIMG("ID_A9639187B3144C57A2BE5AE757FE7972",1) | B16: {=IFERROR(INDEX($AL$2:$AL$18,MATCH(ADDRESS(ROW(),COLUMN(),4),$AM$2:$AM$18,0)),$AE$16)} -> =DISPIMG("ID_A9639187B3144C57A2BE5AE757FE7972",1) | C16: {=IFERROR(INDEX($AL$2:$AL$18,MATCH(ADDRESS(ROW(),COLUMN(),4),$AM$2:$AM$18,0)),$AE$17)} -> =DISPIMG("ID_EA67415A0995455ABF527BB2D12AD119",1) | D16: {=IFERROR(INDEX($AL$2:$AL$18,MATCH(ADDRESS(ROW(),COLUMN(),4),$AM$2:$AM$18,0)),$AE$17)} -> =DISPIMG("ID_EA67415A0995455ABF527BB2D12AD119",1) | E16: {=IFERROR(INDEX($AL$2:$AL$18,MATCH(ADDRESS(ROW(),COLUMN(),4),$AM$2:$AM$18,0)),$AE$17)} -> =DISPIMG("ID_EA67415A0995455ABF527BB2D12AD119",1) | F16: {=IFERROR(INDEX($AL$2:$AL$18,MATCH(ADDRESS(ROW(),COLUMN(),4),$AM$2:$AM$18,0)),$AE$17)} -> =DISPIMG("ID_EA67415A0995455ABF527BB2D12AD119",1) | G16: {=IFERROR(INDEX($AL$2:$AL$18,MATCH(ADDRESS(ROW(),COLUMN(),4),$AM$2:$AM$18,0)),$AE$18)} -> =DISPIMG("ID_76191A7034294A2F8256380F1E832EB7",1) | H16: {=IFERROR(INDEX($AL$2:$AL$18,MATCH(ADDRESS(ROW(),COLUMN(),4),$AM$2:$AM$18,0)),$AE$18)} -> =DISPIMG("ID_76191A7034294A2F8256380F1E832EB7",1) | I16: {=IFERROR(INDEX($AL$2:$AL$18,MATCH(ADDRESS(ROW(),COLUMN(),4),$AM$2:$AM$18,0)),$AE$18)} -> =DISPIMG("ID_76191A7034294A2F8256380F1E832EB7",1) | J16: {=IFERROR(INDEX($AL$2:$AL$18,MATCH(ADDRESS(ROW(),COLUMN(),4),$AM$2:$AM$18,0)),$AE$18)} -> =DISPIMG("ID_76191A7034294A2F8256380F1E832EB7",1) | K16: {=IFERROR(INDEX($AL$2:$AL$18,MATCH(ADDRESS(ROW(),COLUMN(),4),$AM$2:$AM$18,0)),$AE$18)} -> =DISPIMG("ID_76191A7034294A2F8256380F1E832EB7",1) | L16: {=IFERROR(INDEX($AL$2:$AL$18,MATCH(ADDRESS(ROW(),COLUMN(),4),$AM$2:$AM$18,0)),$AE$18)} -> =DISPIMG("ID_76191A7034294A2F8256380F1E832EB7",1) | M16: {=IFERROR(INDEX($AL$2:$AL$18,MATCH(ADDRESS(ROW(),COLUMN(),4),$AM$2:$AM$18,0)),$AE$18)} -> =DISPIMG("ID_76191A7034294A2F8256380F1E832EB7",1) | N16: {=IFERROR(INDEX($AL$2:$AL$18,MATCH(ADDRESS(ROW(),COLUMN(),4),$AM$2:$AM$18,0)),$AE$18)} -> =DISPIMG("ID_76191A7034294A2F8256380F1E832EB7",1) | ... AD16: {=IFERROR(INDEX($AL$2:$AL$18,MATCH(ADDRESS(ROW(),COLUMN(),4),$AM$2:$AM$18,0)),$AE$18)} -> =DISPIMG("ID_76191A7034294A2F8256380F1E832EB7",1) | AE16: =_xlfn.DISPIMG("ID_A9639187B3144C57A2BE5AE757FE7972",1) -> =DISPIMG("ID_A9639187B3144C57A2BE5AE757FE7972",1) | AF16: 太空 | AG16: / | AJ16: 3 | AK16: 三 | AO16: =IFERROR([1]数据!N42,"") -> 0 | AP16: =IFERROR([1]数据!O42,"") -> 0 | AQ16: =IFERROR([1]数据!P42,"") -> 0 | AR16: =IFERROR([1]数据!Q42,"") -> 0
